<?xml version="1.0"?>

<!-- XML namespaces -->

<robot xmlns:sensor="http://playerstage.sourceforge.net/gazebo/xmlschema/#sensor"
       xmlns:controller="http://playerstage.sourceforge.net/gazebo/xmlschema/#controller"
       xmlns:interface="http://playerstage.sourceforge.net/gazebo/xmlschema/#interface"
       xmlns:xacro="http://ros.org/wiki/xacro" 
	   name="arms">
    
 	<!-- ============================   Body   ============================ -->

	<link name="gantry_base_link" >
        </link>

	<!-- =================== Gantry X-Y-Z ============================= -->

	<link name="gantry_x_axis" >
        </link>

	<link name="gantry_y_axis" >
        </link>

	<link name="gantry_z_axis" >
          <visual>
            <geometry>
              <box size="0.0889 0.0508 0.9144"/>
            </geometry>
            <origin xyz="0 0 0" rpy="0 0 0" />
	    <material name="blue">
              <color rgba="0 0 .8 1"/>
	    </material>
	  </visual>
        </link> 

	<!-- =================== Gantry Yaw-Pitch-Roll ============================= -->

	<link name="gimbal_base_link" >
          <visual>
            <geometry>
              <mesh filename="package://arm_description/meshes/gimbal_base.stl"/>
            </geometry>
            <origin xyz="0 0 0" rpy="0 0 0" />
	    <material name="black">
              <color rgba="0.1 0.1 0.1 0.9"/>
	    </material>
	  </visual>
        </link>

	<link name="gimbal_yaw_link" >
          <visual>
            <geometry>
              <mesh filename="package://arm_description/meshes/gimbal_yaw.stl"/>
            </geometry>
            <origin xyz="0 0 0" rpy="0 0 0" />
	    <material name="blue">
              <color rgba="0 0 .8 1"/>
	    </material>
	  </visual>
        </link>

	<link name="gimbal_pitch_link" >
          <visual>
            <geometry>
              <mesh filename="package://arm_description/meshes/gimbal_pitch.stl"/>
            </geometry>
            <origin xyz="0 0 0" rpy="0 0 0" />
	    <material name="black">
              <color rgba="0.1 0.1 0.1 0.9"/>
	    </material>
	  </visual>
        </link>

	<link name="gimbal_roll_link" >
          <visual>
            <geometry>
              <mesh filename="package://arm_description/meshes/gimbal_roll.stl"/>
            </geometry>
            <origin xyz="0 0 0" rpy="0 0 0" />
	    <material name="blue">
              <color rgba="0 0 .8 1"/>
	    </material>
	  </visual>
        </link>


	<!-- =================== Joint Definitions ======================== -->

	<!-- =================== Gantry X-Y-Z ============================= -->

	<joint name="gantry_x_axis_joint" type="prismatic">
    	  <parent link="gantry_base_link" />
    	  <child link="gantry_x_axis" />
    	  <origin xyz="0 0 0" rpy="0 0 0" />
	  <axis xyz="1 0 0" />
    	  <limit lower="0" upper="5" effort="10" velocity="3" />
	</joint>

	<joint name="gantry_y_axis_joint" type="prismatic">
	  <parent link="gantry_x_axis" />
    	  <child link="gantry_y_axis" />
    	  <origin xyz="0 0 0" rpy="0 0 0" />
	  <axis xyz="0 1 0" />
	  <limit lower="0" upper="5" effort="10" velocity="3" />	
	</joint>

	<joint name="gantry_z_axis_joint" type="prismatic">
    	  <parent link="gantry_y_axis" />
    	  <child link="gantry_z_axis" />
    	  <origin xyz="0 0 0" rpy="0 0 0" />
	  <axis xyz="0 0 1" />
	  <limit lower="0" upper="5" effort="10" velocity="3" />	
	</joint>

	<joint name="gantry_to_gimbal_joint" type="fixed">
    	  <parent link="gantry_z_axis" />
    	  <child link="gimbal_base_link" />
          <origin xyz="0 0 -0.4572" rpy="-1.57 0 0" />
	</joint>

	<!-- =================== Gantry Yaw-Pitch-Roll ==================== -->

	<joint name="gimbal_yaw_joint" type="revolute">
    	  <parent link="gimbal_base_link" />
    	  <child link="gimbal_yaw_link" />
	  <origin xyz="0 0 0" rpy="0 0 0" />
	  <axis xyz="0 1 0" />
          <limit lower="-1.57" upper="1.57" effort="10" velocity="3" />
	</joint>

	<joint name="gimbal_pitch_joint" type="revolute">
    	  <parent link="gimbal_yaw_link" />
    	  <child link="gimbal_pitch_link" />
    	  <origin xyz="0 0 0" rpy="0 0 0" />
    	  <axis xyz="1 0 0" />
    	  <limit lower="-0.05" upper="0.05" effort="10" velocity="3" />
	</joint>

	<joint name="gimbal_roll_joint" type="revolute">
    	  <parent link="gimbal_pitch_link" />
    	  <child link="gimbal_roll_link" />
   	  <origin xyz="0 0 0" rpy="0 0 0" />
    	  <axis xyz="0 0 1" />
    	  <limit lower="-0.05" upper="0.05" effort="10" velocity="3" />
	</joint>

	<!-- =================== Torso ======================= -->


	<!-- =================== Left Arm ==================== -->


	<!-- =================== Gazebo ==================== -->

	<gazebo reference="mmUAV">
  	</gazebo>

</robot>

