<robot
  name="mk2">
  <link
    name="torso_base_link">
    <inertial>
      <origin
        xyz="-0.000184028061416036 0.0110303559280557 0.000311245853605478"
        rpy="0 0 0" />
      <mass
        value="0.130487655760344" />
      <inertia
        ixx="0.000205865272154098"
        ixy="1.95212944651905E-07"
        ixz="1.28321175626756E-06"
        iyy="0.000494477771891756"
        iyz="-3.14521016025968E-07"
        izz="0.000320493942072279" />
    </inertial>
    <visual>
      <origin
        xyz="0 0 0"
        rpy="0 0 0" />
      <geometry>
        <mesh
          filename="package://mk2/meshes/torso_base_link.STL" />
      </geometry>
      <material
        name="">
        <color
          rgba="0.792156862745098 0.819607843137255 0.933333333333333 1" />
      </material>
    </visual>
    <collision>
      <origin
        xyz="0 0 0"
        rpy="0 0 0" />
      <geometry>
        <mesh
          filename="package://mk2/meshes/torso_base_link.STL" />
      </geometry>
    </collision>
  </link>
  <link
    name="torso_yaw_link">
    <inertial>
      <origin
        xyz="-1.06641135807935E-08 0.0628988812468705 2.53250616633578E-09"
        rpy="0 0 0" />
      <mass
        value="0.312439405406118" />
      <inertia
        ixx="0.000737785373037655"
        ixy="5.40470742840154E-11"
        ixz="2.42455236911911E-10"
        iyy="0.00155225038783166"
        iyz="-1.8096915920041E-11"
        izz="0.00179835095301137" />
    </inertial>
    <visual>
      <origin
        xyz="0 0 0"
        rpy="0 0 0" />
      <geometry>
        <mesh
          filename="package://mk2/meshes/torso_yaw_link.STL" />
      </geometry>
      <material
        name="">
        <color
          rgba="0.792156862745098 0.819607843137255 0.933333333333333 1" />
      </material>
    </visual>
    <collision>
      <origin
        xyz="0 0 0"
        rpy="0 0 0" />
      <geometry>
        <mesh
          filename="package://mk2/meshes/torso_yaw_link.STL" />
      </geometry>
    </collision>
  </link>
  <joint
    name="torso_yaw_joint"
    type="continuous">
    <origin
      xyz="0 0.01 0"
      rpy="0 1.57 0" />
    <parent
      link="torso_base_link" />
    <child
      link="torso_yaw_link" />
    <axis
      xyz="0 1 0" />
  </joint>
  <link
    name="torso_pitch_link">
    <inertial>
      <origin
        xyz="3.71536021860661E-07 0.0385336088285087 -0.00216821570459847"
        rpy="0 0 0" />
      <mass
        value="0.214939253072605" />
      <inertia
        ixx="0.000647224222348535"
        ixy="4.13577050134442E-09"
        ixz="3.35454012486391E-09"
        iyy="0.000481992877291182"
        iyz="-2.12337487574033E-05"
        izz="0.000508203919522507" />
    </inertial>
    <visual>
      <origin
        xyz="0 0 0"
        rpy="0 0 0" />
      <geometry>
        <mesh
          filename="package://mk2/meshes/torso_pitch_link.STL" />
      </geometry>
      <material
        name="">
        <color
          rgba="0.792156862745098 0.819607843137255 0.933333333333333 1" />
      </material>
    </visual>
    <collision>
      <origin
        xyz="0 0 0"
        rpy="0 0 0" />
      <geometry>
        <mesh
          filename="package://mk2/meshes/torso_pitch_link.STL" />
      </geometry>
    </collision>
  </link>
  <joint
    name="torso_pitch_joint"
    type="continuous">
    <origin
      xyz="0 0.1172 0"
      rpy="0 0 0" />
    <parent
      link="torso_yaw_link" />
    <child
      link="torso_pitch_link" />
    <axis
      xyz="1 0 0" />
  </joint>
  <link
    name="torso_roll_link">
    <inertial>
      <origin
        xyz="6.75249629932648E-08 0.233960353769092 -0.0050067279784306"
        rpy="0 0 0" />
      <mass
        value="0.293335697547887" />
      <inertia
        ixx="0.00578530758836677"
        ixy="-7.31707616710764E-10"
        ixz="-1.75775564632839E-08"
        iyy="0.000677304130480278"
        iyz="-0.000219289414052928"
        izz="0.00606444160061948" />
    </inertial>
    <visual>
      <origin
        xyz="0 0 0"
        rpy="0 0 0" />
      <geometry>
        <mesh
          filename="package://mk2/meshes/torso_roll_link.STL" />
      </geometry>
      <material
        name="">
        <color
          rgba="0.792156862745098 0.819607843137255 0.933333333333333 1" />
      </material>
    </visual>
    <collision>
      <origin
        xyz="0 0 0"
        rpy="0 0 0" />
      <geometry>
        <mesh
          filename="package://mk2/meshes/torso_roll_link.STL" />
      </geometry>
    </collision>
  </link>
  <joint
    name="torso_roll_joint"
    type="continuous">
    <origin
      xyz="0 0.08 0"
      rpy="0 0 0" />
    <parent
      link="torso_pitch_link" />
    <child
      link="torso_roll_link" />
    <axis
      xyz="0 0 -1" />
  </joint>
  <link
    name="right_shoulder_pitch_link">
    <inertial>
      <origin
        xyz="-0.000945723268495749 -5.75524150236983E-05 -0.110098356309085"
        rpy="0 0 0" />
      <mass
        value="0.163443866563097" />
      <inertia
        ixx="0.000541018004036177"
        ixy="-1.62628022066945E-08"
        ixz="9.49719942320387E-06"
        iyy="0.00055998509079004"
        iyz="1.83898457267936E-07"
        izz="0.000176694494660094" />
    </inertial>
    <visual>
      <origin
        xyz="0 0 0"
        rpy="0 0 0" />
      <geometry>
        <mesh
          filename="package://mk2/meshes/right_shoulder_pitch_link.STL" />
      </geometry>
      <material
        name="">
        <color
          rgba="0.792156862745098 0.819607843137255 0.933333333333333 1" />
      </material>
    </visual>
    <collision>
      <origin
        xyz="0 0 0"
        rpy="0 0 0" />
      <geometry>
        <mesh
          filename="package://mk2/meshes/right_shoulder_pitch_link.STL" />
      </geometry>
    </collision>
  </link>
  <joint
    name="right_shoulder_pitch_joint"
    type="continuous">
    <origin
      xyz="-0.0754 0.36378 0"
      rpy="1.5708 -1.5707 1.5708" />
    <parent
      link="torso_roll_link" />
    <child
      link="right_shoulder_pitch_link" />
    <axis
      xyz="0 0 -1" />
  </joint>
  <link
    name="right_shoulder_roll_link">
    <inertial>
      <origin
        xyz="-0.000393320110424783 -0.0428351273894357 -0.00178233794530914"
        rpy="0 0 0" />
      <mass
        value="0.0635014085130222" />
      <inertia
        ixx="9.22926705897114E-05"
        ixy="7.99958336746189E-07"
        ixz="-4.48580587139913E-08"
        iyy="4.64666186767237E-05"
        iyz="-5.63299412392605E-06"
        izz="9.49758908565645E-05" />
    </inertial>
    <visual>
      <origin
        xyz="0 0 0"
        rpy="0 0 0" />
      <geometry>
        <mesh
          filename="package://mk2/meshes/right_shoulder_roll_link.STL" />
      </geometry>
      <material
        name="">
        <color
          rgba="0.792156862745098 0.819607843137255 0.933333333333333 1" />
      </material>
    </visual>
    <collision>
      <origin
        xyz="0 0 0"
        rpy="0 0 0" />
      <geometry>
        <mesh
          filename="package://mk2/meshes/right_shoulder_roll_link.STL" />
      </geometry>
    </collision>
  </link>
  <joint
    name="right_shoulder_roll_joint"
    type="continuous">
    <origin
      xyz="0 0 -0.17412"
      rpy="3.14 -1.57 0" />
    <parent
      link="right_shoulder_pitch_link" />
    <child
      link="right_shoulder_roll_link" />
    <axis
      xyz="0 0 -1" />
  </joint>
  <link
    name="right_shoulder_yaw_link">
    <inertial>
      <origin
        xyz="6.37165040110046E-06 0.00238860497459617 -0.166767878999537"
        rpy="0 0 0" />
      <mass
        value="0.234264177667547" />
      <inertia
        ixx="0.00139590246325816"
        ixy="7.50525687812593E-10"
        ixz="-3.30705012330942E-08"
        iyy="0.00128382682336014"
        iyz="-4.30079647499972E-05"
        izz="0.00033254645794358" />
    </inertial>
    <visual>
      <origin
        xyz="0 0 0"
        rpy="0 0 0" />
      <geometry>
        <mesh
          filename="package://mk2/meshes/right_shoulder_yaw_link.STL" />
      </geometry>
      <material
        name="">
        <color
          rgba="0.792156862745098 0.819607843137255 0.933333333333333 1" />
      </material>
    </visual>
    <collision>
      <origin
        xyz="0 0 0"
        rpy="0 0 0" />
      <geometry>
        <mesh
          filename="package://mk2/meshes/right_shoulder_yaw_link.STL" />
      </geometry>
    </collision>
  </link>
  <joint
    name="right_shoulder_yaw_joint"
    type="continuous">
    <origin
      xyz="0 -0.073 0"
      rpy="-1.57 1.568 0" />
    <parent
      link="right_shoulder_roll_link" />
    <child
      link="right_shoulder_yaw_link" />
    <axis
      xyz="0 0 1" />
  </joint>
  <link
    name="right_elbow_pitch_link">
    <inertial>
      <origin
        xyz="-0.000360440502475634 0.0408954090865386 0.00105765467601504"
        rpy="0 0 0" />
      <mass
        value="0.0687829523644407" />
      <inertia
        ixx="0.000106324772601317"
        ixy="-8.44268471324609E-07"
        ixz="2.61073416339683E-08"
        iyy="5.76141023403317E-05"
        iyz="-2.77922758110826E-06"
        izz="0.000105076946485533" />
    </inertial>
    <visual>
      <origin
        xyz="0 0 0"
        rpy="0 0 0" />
      <geometry>
        <mesh
          filename="package://mk2/meshes/right_elbow_pitch_link.STL" />
      </geometry>
      <material
        name="">
        <color
          rgba="0.792156862745098 0.819607843137255 0.933333333333333 1" />
      </material>
    </visual>
    <collision>
      <origin
        xyz="0 0 0"
        rpy="0 0 0" />
      <geometry>
        <mesh
          filename="package://mk2/meshes/right_elbow_pitch_link.STL" />
      </geometry>
    </collision>
  </link>
  <joint
    name="right_elbow_pitch_joint"
    type="continuous">
    <origin
      xyz="0 0 -0.24462"
      rpy="-1.5708 1.5707 -3.1416" />
    <parent
      link="right_shoulder_yaw_link" />
    <child
      link="right_elbow_pitch_link" />
    <axis
      xyz="0 0 -1" />
  </joint>
  <link
    name="right_wrist_yaw_link">
    <inertial>
      <origin
        xyz="6.83765934338387E-05 -0.0985935102273398 0.00124157512236639"
        rpy="0 0 0" />
      <mass
        value="0.143237901554334" />
      <inertia
        ixx="0.000407431901915526"
        ixy="-1.82700571936414E-07"
        ixz="-1.19533565678743E-08"
        iyy="0.000156695313739821"
        iyz="-8.79427099771474E-06"
        izz="0.000390076332830964" />
    </inertial>
    <visual>
      <origin
        xyz="0 0 0"
        rpy="0 0 0" />
      <geometry>
        <mesh
          filename="package://mk2/meshes/right_wrist_yaw_link.STL" />
      </geometry>
      <material
        name="">
        <color
          rgba="0.792156862745098 0.819607843137255 0.933333333333333 1" />
      </material>
    </visual>
    <collision>
      <origin
        xyz="0 0 0"
        rpy="0 0 0" />
      <geometry>
        <mesh
          filename="package://mk2/meshes/right_wrist_yaw_link.STL" />
      </geometry>
    </collision>
  </link>
  <joint
    name="right_wrist_yaw_joint"
    type="continuous">
    <origin
      xyz="0 0.0732 0"
      rpy="0 0 3.14" />
    <parent
      link="right_elbow_pitch_link" />
    <child
      link="right_wrist_yaw_link" />
    <axis
      xyz="0 -1 0" />
  </joint>
  <link
    name="right_wrist_pitch_link">
    <inertial>
      <origin
        xyz="-0.000408944798772404 -0.0370500000009173 -0.000408944801744304"
        rpy="0 0 0" />
      <mass
        value="0.0439051251850394" />
      <inertia
        ixx="7.67509542483871E-05"
        ixy="1.01266452217356E-06"
        ixz="-7.34251086486088E-09"
        iyy="3.22048578317638E-05"
        iyz="-1.0126645215248E-06"
        izz="7.67509542488895E-05" />
    </inertial>
    <visual>
      <origin
        xyz="0 0 0"
        rpy="0 0 0" />
      <geometry>
        <mesh
          filename="package://mk2/meshes/right_wrist_pitch_link.STL" />
      </geometry>
      <material
        name="">
        <color
          rgba="0.792156862745098 0.819607843137255 0.933333333333333 1" />
      </material>
    </visual>
    <collision>
      <origin
        xyz="0 0 0"
        rpy="0 0 0" />
      <geometry>
        <mesh
          filename="package://mk2/meshes/right_wrist_pitch_link.STL" />
      </geometry>
    </collision>
  </link>
  <joint
    name="right_wrist_pitch_joint"
    type="continuous">
    <origin
      xyz="0 -0.15124 0"
      rpy="0 0 0" />
    <parent
      link="right_wrist_yaw_link" />
    <child
      link="right_wrist_pitch_link" />
    <axis
      xyz="0 0 -1" />
  </joint>
  <link
    name="right_wrist_roll_link">
    <inertial>
      <origin
        xyz="0.00215013326717001 -0.0219675542935256 0.00061794100279644"
        rpy="0 0 0" />
      <mass
        value="0.0825624287077396" />
      <inertia
        ixx="0.000108263415959971"
        ixy="3.36877167007395E-06"
        ixz="-1.09626858677818E-07"
        iyy="9.54648112890784E-05"
        iyz="-1.58400249287222E-06"
        izz="0.000125428179179394" />
    </inertial>
    <visual>
      <origin
        xyz="0 0 0"
        rpy="0 0 0" />
      <geometry>
        <mesh
          filename="package://mk2/meshes/right_wrist_roll_link.STL" />
      </geometry>
      <material
        name="">
        <color
          rgba="0.792156862745098 0.819607843137255 0.933333333333333 1" />
      </material>
    </visual>
    <collision>
      <origin
        xyz="0 0 0"
        rpy="0 0 0" />
      <geometry>
        <mesh
          filename="package://mk2/meshes/right_wrist_roll_link.STL" />
      </geometry>
    </collision>
  </link>
  <joint
    name="right_wrist_roll_joint"
    type="continuous">
    <origin
      xyz="0 -0.07 0"
      rpy="0.001 0 0" />
    <parent
      link="right_wrist_pitch_link" />
    <child
      link="right_wrist_roll_link" />
    <axis
      xyz="1 0 0" />
  </joint>
  <link
    name="right_palm_link">
    <inertial>
      <origin
        xyz="0.00332509636151379 -6.34020015467807E-05 -0.00171511307591515"
        rpy="0 0 0" />
      <mass
        value="0.284273792034029" />
      <inertia
        ixx="0.000741347138520517"
        ixy="-3.32765316438203E-07"
        ixz="-4.99009095684782E-05"
        iyy="0.000904993784399885"
        iyz="2.51958104939037E-06"
        izz="0.000336850361367501" />
    </inertial>
    <visual>
      <origin
        xyz="0 0 0"
        rpy="0 0 0" />
      <geometry>
        <mesh
          filename="package://mk2/meshes/right_palm_link.STL" />
      </geometry>
      <material
        name="">
        <color
          rgba="0.792156862745098 0.819607843137255 0.933333333333333 1" />
      </material>
    </visual>
    <collision>
      <origin
        xyz="0 0 0"
        rpy="0 0 0" />
      <geometry>
        <mesh
          filename="package://mk2/meshes/right_palm_link.STL" />
      </geometry>
    </collision>
  </link>
  <joint
    name="right_palm_joint"
    type="fixed">
    <origin
      xyz="0 -0.14894 0"
      rpy="-1.57 0 3.14" />
    <parent
      link="right_wrist_roll_link" />
    <child
      link="right_palm_link" />
    <axis
      xyz="0 0 0" />
  </joint>
  <link
    name="right_thumb_yaw_link">
    <inertial>
      <origin
        xyz="-0.000203239979217007 -0.0161010824892298 0.0172969075913921"
        rpy="0 0 0" />
      <mass
        value="0.0873520755411569" />
      <inertia
        ixx="5.84732510726915E-05"
        ixy="7.64694611217194E-07"
        ixz="7.66748794077659E-08"
        iyy="4.01053877368933E-05"
        iyz="2.75415529214724E-06"
        izz="6.67239800431704E-05" />
    </inertial>
    <visual>
      <origin
        xyz="0 0 0"
        rpy="0 0 0" />
      <geometry>
        <mesh
          filename="package://mk2/meshes/right_thumb_yaw_link.STL" />
      </geometry>
      <material
        name="">
        <color
          rgba="0.792156862745098 0.819607843137255 0.933333333333333 1" />
      </material>
    </visual>
    <collision>
      <origin
        xyz="0 0 0"
        rpy="0 0 0" />
      <geometry>
        <mesh
          filename="package://mk2/meshes/right_thumb_yaw_link.STL" />
      </geometry>
    </collision>
  </link>
  <joint
    name="right_thumb_yaw_joint"
    type="continuous">
    <origin
      xyz="-0.015 0 0"
      rpy="3.14 0 1.57" />
    <parent
      link="right_palm_link" />
    <child
      link="right_thumb_yaw_link" />
    <axis
      xyz="0 0 -1" />
  </joint>
  <link
    name="right_thumb_pitch_link">
    <inertial>
      <origin
        xyz="0.0507250537622433 0.00923483454652496 0.00764091598897373"
        rpy="0 0 0" />
      <mass
        value="0.0183440420213234" />
      <inertia
        ixx="3.2013176266787E-06"
        ixy="3.27751281132962E-06"
        ixz="-4.34996627297777E-10"
        iyy="1.3363848080228E-05"
        iyz="4.95219960159234E-11"
        izz="1.38624655769229E-05" />
    </inertial>
    <visual>
      <origin
        xyz="0 0 0"
        rpy="0 0 0" />
      <geometry>
        <mesh
          filename="package://mk2/meshes/right_thumb_pitch_link.STL" />
      </geometry>
      <material
        name="">
        <color
          rgba="0.792156862745098 0.819607843137255 0.933333333333333 1" />
      </material>
    </visual>
    <collision>
      <origin
        xyz="0 0 0"
        rpy="0 0 0" />
      <geometry>
        <mesh
          filename="package://mk2/meshes/right_thumb_pitch_link.STL" />
      </geometry>
    </collision>
  </link>
  <joint
    name="right_thumb_pitch_joint"
    type="continuous">
    <origin
      xyz="0 -0.057 0.013"
      rpy="-1.5708 -0.055 -1.5708" />
    <parent
      link="right_thumb_yaw_link" />
    <child
      link="right_thumb_pitch_link" />
    <axis
      xyz="0 0 1" />
  </joint>
  <link
    name="right_index_finger_link">
    <inertial>
      <origin
        xyz="0.0507250537591674 0.00923483453679322 -1.58401708660882E-06"
        rpy="0 0 0" />
      <mass
        value="0.0183440420046593" />
      <inertia
        ixx="3.20131760953375E-06"
        ixy="3.27751280342657E-06"
        ixz="-4.34997901856755E-10"
        iyy="1.33638480471983E-05"
        iyz="4.9518474834498E-11"
        izz="1.38624655514328E-05" />
    </inertial>
    <visual>
      <origin
        xyz="0 0 0"
        rpy="0 0 0" />
      <geometry>
        <mesh
          filename="package://mk2/meshes/right_index_finger_link.STL" />
      </geometry>
      <material
        name="">
        <color
          rgba="0.792156862745098 0.819607843137255 0.933333333333333 1" />
      </material>
    </visual>
    <collision>
      <origin
        xyz="0 0 0"
        rpy="0 0 0" />
      <geometry>
        <mesh
          filename="package://mk2/meshes/right_index_finger_link.STL" />
      </geometry>
    </collision>
  </link>
  <joint
    name="right_index_finger_joint"
    type="continuous">
    <origin
      xyz="-0.03 0 0.07"
      rpy="1.5708 -1.5154 1.5708" />
    <parent
      link="right_palm_link" />
    <child
      link="right_index_finger_link" />
    <axis
      xyz="0 0 -1" />
  </joint>
  <link
    name="right_middle_finger_link">
    <inertial>
      <origin
        xyz="0.0507250500930794 0.00923483358610872 0.0153939641150334"
        rpy="0 0 0" />
      <mass
        value="0.0183440402915455" />
      <inertia
        ixx="3.2013173480543E-06"
        ixy="3.27751211478389E-06"
        ixz="-4.35455803577331E-10"
        iyy="1.33638453239676E-05"
        iyz="4.93965820544238E-11"
        izz="1.38624627278259E-05" />
    </inertial>
    <visual>
      <origin
        xyz="0 0 0"
        rpy="0 0 0" />
      <geometry>
        <mesh
          filename="package://mk2/meshes/right_middle_finger_link.STL" />
      </geometry>
      <material
        name="">
        <color
          rgba="0.792156862745098 0.819607843137255 0.933333333333333 1" />
      </material>
    </visual>
    <collision>
      <origin
        xyz="0 0 0"
        rpy="0 0 0" />
      <geometry>
        <mesh
          filename="package://mk2/meshes/right_middle_finger_link.STL" />
      </geometry>
    </collision>
  </link>
  <joint
    name="right_middle_finger_joint"
    type="continuous">
    <origin
      xyz="0.004 0 0.07"
      rpy="1.5708 -1.5154 1.5708" />
    <parent
      link="right_palm_link" />
    <child
      link="right_middle_finger_link" />
    <axis
      xyz="0 0 -1" />
  </joint>
</robot>
