<robot
  name="mk2">
  <link
    name="torso_roll_link">
    <inertial>
      <origin
        xyz="6.75249629932648E-08 0.233960353769092 -0.0050067279784306"
        rpy="0 0 0" />
      <mass
        value="0.293335697547887" />
      <inertia
        ixx="0.00578530758836677"
        ixy="-7.31707616710764E-10"
        ixz="-1.75775564632839E-08"
        iyy="0.000677304130480278"
        iyz="-0.000219289414052928"
        izz="0.00606444160061948" />
    </inertial>
    <visual>
      <origin
        xyz="0 0 0"
        rpy="0 0 0" />
      <geometry>
        <mesh
          filename="package://mk2/meshes/torso_roll_link.STL" />
      </geometry>
      <material
        name="">
        <color
          rgba="0.792156862745098 0.819607843137255 0.933333333333333 1" />
      </material>
    </visual>
    <collision>
      <origin
        xyz="0 0 0"
        rpy="0 0 0" />
      <geometry>
        <mesh
          filename="package://mk2/meshes/torso_roll_link.STL" />
      </geometry>
    </collision>
  </link>
  <link
    name="right_shoulder_pitch_link">
    <inertial>
      <origin
        xyz="-0.000945723268495749 -5.75524150236983E-05 -0.110098356309085"
        rpy="0 0 0" />
      <mass
        value="0.163443866563097" />
      <inertia
        ixx="0.000541018004036177"
        ixy="-1.62628022066945E-08"
        ixz="9.49719942320387E-06"
        iyy="0.00055998509079004"
        iyz="1.83898457267936E-07"
        izz="0.000176694494660094" />
    </inertial>
    <visual>
      <origin
        xyz="0 0 0"
        rpy="1.57 -1.57 1.57" />
      <geometry>
        <mesh
          filename="package://mk2/meshes/right_shoulder_pitch_link.STL" />
      </geometry>
      <material
        name="">
        <color
          rgba="0.792156862745098 0.819607843137255 0.933333333333333 1" />
      </material>
    </visual>
    <collision>
      <origin
        xyz="0 0 0"
        rpy="0 0 0" />
      <geometry>
        <mesh
          filename="package://mk2/meshes/right_shoulder_pitch_link.STL" />
      </geometry>
    </collision>
  </link>
  <joint
    name="right_shoulder_pitch_joint"
    type="revolute">
    <origin
      xyz="-0.0754 0.36378 0"
      rpy="0 0 0" />
    <parent
      link="torso_roll_link" />
    <child
      link="right_shoulder_pitch_link" />
    <axis
      xyz="1 0 0" />
    <limit 
      effort="30" velocity="1.0" lower="-1.57" upper="1.57" />
  </joint>
  <link
    name="right_shoulder_roll_link">
    <inertial>
      <origin
        xyz="-0.000393320110424783 -0.0428351273894357 -0.00178233794530914"
        rpy="0 0 0" />
      <mass
        value="0.0635014085130222" />
      <inertia
        ixx="9.22926705897114E-05"
        ixy="7.99958336746189E-07"
        ixz="-4.48580587139913E-08"
        iyy="4.64666186767237E-05"
        iyz="-5.63299412392605E-06"
        izz="9.49758908565645E-05" />
    </inertial>
    <visual>
      <origin
        xyz="0 0 0"
        rpy="0 0 0" />
      <geometry>
        <mesh
          filename="package://mk2/meshes/right_shoulder_roll_link.STL" />
      </geometry>
      <material
        name="">
        <color
          rgba="0.792156862745098 0.819607843137255 0.933333333333333 1" />
      </material>
    </visual>
    <collision>
      <origin
        xyz="0 0 0"
        rpy="0 0 0" />
      <geometry>
        <mesh
          filename="package://mk2/meshes/right_shoulder_roll_link.STL" />
      </geometry>
    </collision>
  </link>
  <joint
    name="right_shoulder_roll_joint"
    type="revolute">
    <origin
      xyz="-0.17412 0 0"
      rpy="0 0 0" />
    <parent
      link="right_shoulder_pitch_link" />
    <child
      link="right_shoulder_roll_link" />
    <axis
      xyz="0 0 -1" />
    <limit 
      effort="30" velocity="1.0" lower="-0.4" upper="3.14" />
  </joint>
  <link
    name="right_shoulder_yaw_link">
    <inertial>
      <origin
        xyz="6.37165040110046E-06 0.00238860497459617 -0.166767878999537"
        rpy="0 0 0" />
      <mass
        value="0.234264177667547" />
      <inertia
        ixx="0.00139590246325816"
        ixy="7.50525687812593E-10"
        ixz="-3.30705012330942E-08"
        iyy="0.00128382682336014"
        iyz="-4.30079647499972E-05"
        izz="0.00033254645794358" />
    </inertial>
    <visual>
      <origin
        xyz="0 0 0"
        rpy="-1.57 1.57 0" />
      <geometry>
        <mesh
          filename="package://mk2/meshes/right_shoulder_yaw_link.STL" />
      </geometry>
      <material
        name="">
        <color
          rgba="0.792156862745098 0.819607843137255 0.933333333333333 1" />
      </material>
    </visual>
    <collision>
      <origin
        xyz="0 0 0"
        rpy="0 0 0" />
      <geometry>
        <mesh
          filename="package://mk2/meshes/right_shoulder_yaw_link.STL" />
      </geometry>
    </collision>
  </link>
  <joint
    name="right_shoulder_yaw_joint"
    type="revolute">
    <origin
      xyz="0 -0.073 0"
      rpy="0 0 0" />
    <parent
      link="right_shoulder_roll_link" />
    <child
      link="right_shoulder_yaw_link" />
    <axis
      xyz="0 1 0" />
    <limit 
      effort="30" velocity="1.0" lower="-1.57" upper="1.57" />
  </joint>
  <link
    name="right_elbow_pitch_link">
    <inertial>
      <origin
        xyz="-0.000360440502475634 0.0408954090865386 0.00105765467601504"
        rpy="0 0 0" />
      <mass
        value="0.0687829523644407" />
      <inertia
        ixx="0.000106324772601317"
        ixy="-8.44268471324609E-07"
        ixz="2.61073416339683E-08"
        iyy="5.76141023403317E-05"
        iyz="-2.77922758110826E-06"
        izz="0.000105076946485533" />
    </inertial>
    <visual>
      <origin
        xyz="0 0 0"
        rpy="0 1.57 3.14" />
      <geometry>
        <mesh
          filename="package://mk2/meshes/right_elbow_pitch_link.STL" />
      </geometry>
      <material
        name="">
        <color
          rgba="0.792156862745098 0.819607843137255 0.933333333333333 1" />
      </material>
    </visual>
    <collision>
      <origin
        xyz="0 0 0"
        rpy="0 0 0" />
      <geometry>
        <mesh
          filename="package://mk2/meshes/right_elbow_pitch_link.STL" />
      </geometry>
    </collision>
  </link>
  <joint
    name="right_elbow_pitch_joint"
    type="revolute">
    <origin
      xyz="0 -0.24462 0"
      rpy="0 0 0" />
    <parent
      link="right_shoulder_yaw_link" />
    <child
      link="right_elbow_pitch_link" />
    <axis
      xyz="-1 0 0" />
    <limit 
      effort="30" velocity="1.0" lower="-3.14" upper="3.14" />
  </joint>
  <link
    name="right_wrist_yaw_link">
    <inertial>
      <origin
        xyz="6.83765934338387E-05 -0.0985935102273398 0.00124157512236639"
        rpy="0 0 0" />
      <mass
        value="0.143237901554334" />
      <inertia
        ixx="0.000407431901915526"
        ixy="-1.82700571936414E-07"
        ixz="-1.19533565678743E-08"
        iyy="0.000156695313739821"
        iyz="-8.79427099771474E-06"
        izz="0.000390076332830964" />
    </inertial>
    <visual>
      <origin
        xyz="0 0 0"
        rpy="0 1.57 0" />
      <geometry>
        <mesh
          filename="package://mk2/meshes/right_wrist_yaw_link.STL" />
      </geometry>
      <material
        name="">
        <color
          rgba="0.792156862745098 0.819607843137255 0.933333333333333 1" />
      </material>
    </visual>
    <collision>
      <origin
        xyz="0 0 0"
        rpy="0 0 0" />
      <geometry>
        <mesh
          filename="package://mk2/meshes/right_wrist_yaw_link.STL" />
      </geometry>
    </collision>
  </link>
  <joint
    name="right_wrist_yaw_joint"
    type="revolute">
    <origin
      xyz="0 -0.0732 0"
      rpy="0 0 0" />
    <parent
      link="right_elbow_pitch_link" />
    <child
      link="right_wrist_yaw_link" />
    <axis
      xyz="0 1 0" />
    <limit 
      effort="30" velocity="1.0" lower="-1.57" upper="1.57" />
  </joint>
  <link
    name="right_wrist_pitch_link">
    <inertial>
      <origin
        xyz="-0.000408944798772404 -0.0370500000009173 -0.000408944801744304"
        rpy="0 0 0" />
      <mass
        value="0.0439051251850394" />
      <inertia
        ixx="7.67509542483871E-05"
        ixy="1.01266452217356E-06"
        ixz="-7.34251086486088E-09"
        iyy="3.22048578317638E-05"
        iyz="-1.0126645215248E-06"
        izz="7.67509542488895E-05" />
    </inertial>
    <visual>
      <origin
        xyz="0 0 0"
        rpy="0 1.57 0" />
      <geometry>
        <mesh
          filename="package://mk2/meshes/right_wrist_pitch_link.STL" />
      </geometry>
      <material
        name="">
        <color
          rgba="0.792156862745098 0.819607843137255 0.933333333333333 1" />
      </material>
    </visual>
    <collision>
      <origin
        xyz="0 0 0"
        rpy="0 0 0" />
      <geometry>
        <mesh
          filename="package://mk2/meshes/right_wrist_pitch_link.STL" />
      </geometry>
    </collision>
  </link>
  <joint
    name="right_wrist_pitch_joint"
    type="revolute">
    <origin
      xyz="0 -0.15124 0"
      rpy="0 0 0" />
    <parent
      link="right_wrist_yaw_link" />
    <child
      link="right_wrist_pitch_link" />
    <axis
      xyz="1 0 0" />
    <limit 
      effort="30" velocity="1.0" lower="-1.57" upper="1.57" />
  </joint>
  <link
    name="right_wrist_roll_link">
    <inertial>
      <origin
        xyz="0.00215013326717001 -0.0219675542935256 0.00061794100279644"
        rpy="0 0 0" />
      <mass
        value="0.0825624287077396" />
      <inertia
        ixx="0.000108263415959971"
        ixy="3.36877167007395E-06"
        ixz="-1.09626858677818E-07"
        iyy="9.54648112890784E-05"
        iyz="-1.58400249287222E-06"
        izz="0.000125428179179394" />
    </inertial>
    <visual>
      <origin
        xyz="0 0 0"
        rpy="0 1.57 0" />
      <geometry>
        <mesh
          filename="package://mk2/meshes/right_wrist_roll_link.STL" />
      </geometry>
      <material
        name="">
        <color
          rgba="0.792156862745098 0.819607843137255 0.933333333333333 1" />
      </material>
    </visual>
    <collision>
      <origin
        xyz="0 0 0"
        rpy="0 0 0" />
      <geometry>
        <mesh
          filename="package://mk2/meshes/right_wrist_roll_link.STL" />
      </geometry>
    </collision>
  </link>
  <joint
    name="right_wrist_roll_joint"
    type="revolute">
    <origin
      xyz="0 -0.07 0"
      rpy="0 0 0" />
    <parent
      link="right_wrist_pitch_link" />
    <child
      link="right_wrist_roll_link" />
    <axis
      xyz="0 0 1" />
    <limit 
      effort="30" velocity="1.0" lower="-1.57" upper="1.57" />
  </joint>
</robot>
