<robot
  name="mk2_arm">
  <link
    name="base_link">
    <inertial>
      <origin
        xyz="-0.0050067 -6.7525E-08 -0.44116"
        rpy="0 0 0" />
      <mass
        value="0.29334" />
      <inertia
        ixx="0.0060644"
        ixy="1.7578E-08"
        ixz="0.00021929"
        iyy="0.0057853"
        iyz="-7.3171E-10"
        izz="0.0006773" />
    </inertial>
    <visual>
      <origin
        xyz="0 0 0"
        rpy="0 0 0" />
      <geometry>
        <mesh
          filename="package://mk2/meshes/base_link.STL" />
      </geometry>
      <material
        name="">
        <color
          rgba="0.79216 0.81961 0.93333 1" />
      </material>
    </visual>
    <collision>
      <origin
        xyz="0 0 0"
        rpy="0 0 0" />
      <geometry>
        <mesh
          filename="package://mk2/meshes/base_link.STL" />
      </geometry>
    </collision>
  </link>
  <link
    name="link_1">
    <inertial>
      <origin
        xyz="-0.0012351 -0.11113 4.8396E-05"
        rpy="0 0 0" />
      <mass
        value="0.14015" />
      <inertia
        ixx="0.00052809"
        ixy="1.0634E-05"
        ixz="1.2129E-08"
        iyy="0.00016132"
        iyz="-1.7619E-07"
        izz="0.00054642" />
    </inertial>
    <visual>
      <origin
        xyz="0 0 0"
        rpy="0 0 0" />
      <geometry>
        <mesh
          filename="package://mk2/meshes/link_1.STL" />
      </geometry>
      <material
        name="">
        <color
          rgba="0.79216 0.81961 0.93333 1" />
      </material>
    </visual>
    <collision>
      <origin
        xyz="0 0 0"
        rpy="0 0 0" />
      <geometry>
        <mesh
          filename="package://mk2/meshes/link_1.STL" />
      </geometry>
    </collision>
  </link>
  <joint
    name="joint_1"
    type="revolute">
    <origin
      xyz="0 -0.0754 -0.57098"
      rpy="0 0 0" />
    <parent
      link="base_link" />
    <child
      link="link_1" />
    <axis
      xyz="0 1 0" />
    <limit
      lower="-1.57"
      upper="1.57"
      effort="10"
      velocity="2" />
  </joint>
  <link
    name="link_2">
    <inertial>
      <origin
        xyz="0.0017823 0.00039333 -0.042835"
        rpy="0 0 0" />
      <mass
        value="0.063501" />
      <inertia
        ixx="9.4976E-05"
        ixy="-4.4859E-08"
        ixz="5.633E-06"
        iyy="9.2293E-05"
        iyz="-7.9997E-07"
        izz="4.6467E-05" />
    </inertial>
    <visual>
      <origin
        xyz="0 0 0"
        rpy="0 0 0" />
      <geometry>
        <mesh
          filename="package://mk2/meshes/link_2.STL" />
      </geometry>
      <material
        name="">
        <color
          rgba="0.79216 0.81961 0.93333 1" />
      </material>
    </visual>
    <collision>
      <origin
        xyz="0 0 0"
        rpy="0 0 0" />
      <geometry>
        <mesh
          filename="package://mk2/meshes/link_2.STL" />
      </geometry>
    </collision>
  </link>
  <joint
    name="joint_2"
    type="revolute">
    <origin
      xyz="0 -0.17412 0"
      rpy="0 0 0" />
    <parent
      link="link_1" />
    <child
      link="link_2" />
    <axis
      xyz="1 0 0" />
    <limit
      lower="-1.57"
      upper="1.57"
      effort="10"
      velocity="2" />
  </joint>
  <link
    name="link_3">
    <inertial>
      <origin
        xyz="-1.69153692332121E-06 0.00238858963512392 -0.166767903309812"
        rpy="0 0 0" />
      <mass
        value="0.234264171591375" />
      <inertia
        ixx="0.00139590207979836"
        ixy="7.51245956056208E-10"
        ixz="-3.30706766930798E-08"
        iyy="0.00128382645270641"
        iyz="-4.30079651246562E-05"
        izz="0.000332546446199722" />
    </inertial>
    <visual>
      <origin
        xyz="0 0 0"
        rpy="0 0 0" />
      <geometry>
        <mesh
          filename="package://mk2/meshes/link_3.STL" />
      </geometry>
      <material
        name="">
        <color
          rgba="0.792156862745098 0.819607843137255 0.933333333333333 1" />
      </material>
    </visual>
    <collision>
      <origin
        xyz="0 0 0"
        rpy="0 0 0" />
      <geometry>
        <mesh
          filename="package://mk2/meshes/link_3.STL" />
      </geometry>
    </collision>
  </link>
  <joint
    name="joint_3"
    type="revolute">
    <origin
      xyz="0 0 -0.07335"
      rpy="0 0 0" />
    <parent
      link="link_2" />
    <child
      link="link_3" />
    <axis
      xyz="0 0 1" />
    <limit
      lower="-1.57"
      upper="1.57"
      effort="10"
      velocity="2" />
  </joint>
  <link
    name="link_4">
    <inertial>
      <origin
        xyz="0.0408954089550636 -0.0010576700193137 0.000360440534411199"
        rpy="0 0 0" />
      <mass
        value="0.0687829534109676" />
      <inertia
        ixx="5.76141024853575E-05"
        ixy="2.77922763557682E-06"
        ixz="8.44268422594664E-07"
        iyy="0.00010507694664325"
        iyz="2.61073450621177E-08"
        izz="0.000106324772882937" />
    </inertial>
    <visual>
      <origin
        xyz="0 0 0"
        rpy="0 0 0" />
      <geometry>
        <mesh
          filename="package://mk2/meshes/link_4.STL" />
      </geometry>
      <material
        name="">
        <color
          rgba="0.792156862745098 0.819607843137255 0.933333333333333 1" />
      </material>
    </visual>
    <collision>
      <origin
        xyz="0 0 0"
        rpy="0 0 0" />
      <geometry>
        <mesh
          filename="package://mk2/meshes/link_4.STL" />
      </geometry>
    </collision>
  </link>
  <joint
    name="joint_4"
    type="revolute">
    <origin
      xyz="0 0 -0.24463"
      rpy="0 0 0" />
    <parent
      link="link_3" />
    <child
      link="link_4" />
    <axis
      xyz="0 1 0" />
    <limit
      lower="-1.57"
      upper="1.57"
      effort="10"
      velocity="2" />
  </joint>
  <link
    name="link_5">
    <inertial>
      <origin
        xyz="0.098444 -0.0012416 6.8382E-05"
        rpy="0 0 0" />
      <mass
        value="0.14324" />
      <inertia
        ixx="0.0001567"
        ixy="-8.7939E-06"
        ixz="1.8263E-07"
        iyy="0.00039008"
        iyz="1.2066E-08"
        izz="0.00040743" />
    </inertial>
    <visual>
      <origin
        xyz="0 0 0"
        rpy="0 0 0" />
      <geometry>
        <mesh
          filename="package://mk2/meshes/link_5.STL" />
      </geometry>
      <material
        name="">
        <color
          rgba="0.79216 0.81961 0.93333 1" />
      </material>
    </visual>
    <collision>
      <origin
        xyz="0 0 0"
        rpy="0 0 0" />
      <geometry>
        <mesh
          filename="package://mk2/meshes/link_5.STL" />
      </geometry>
    </collision>
  </link>
  <joint
    name="joint_5"
    type="revolute">
    <origin
      xyz="0.07335 0 0"
      rpy="0 0 0" />
    <parent
      link="link_4" />
    <child
      link="link_5" />
    <axis
      xyz="1 0 0" />
    <limit
      lower="-1.57"
      upper="1.57"
      effort="10"
      velocity="2" />
  </joint>
  <link
    name="link_6">
    <inertial>
      <origin
        xyz="0.03705 0.00040894 -0.00040894"
        rpy="0 0 0" />
      <mass
        value="0.043905" />
      <inertia
        ixx="3.2205E-05"
        ixy="-1.0127E-06"
        ixz="-1.0127E-06"
        iyy="7.6751E-05"
        iyz="7.3425E-09"
        izz="7.6751E-05" />
    </inertial>
    <visual>
      <origin
        xyz="0 0 0"
        rpy="0 0 0" />
      <geometry>
        <mesh
          filename="package://mk2/meshes/link_6.STL" />
      </geometry>
      <material
        name="">
        <color
          rgba="0.79216 0.81961 0.93333 1" />
      </material>
    </visual>
    <collision>
      <origin
        xyz="0 0 0"
        rpy="0 0 0" />
      <geometry>
        <mesh
          filename="package://mk2/meshes/link_6.STL" />
      </geometry>
    </collision>
  </link>
  <joint
    name="joint_6"
    type="revolute">
    <origin
      xyz="0.1511 0 0"
      rpy="0 0 0" />
    <parent
      link="link_5" />
    <child
      link="link_6" />
    <axis
      xyz="0 1 0" />
    <limit
      lower="-1.57"
      upper="1.57"
      effort="10"
      velocity="2" />
  </joint>
  <link
    name="link_7">
    <inertial>
      <origin
        xyz="0.021968 -0.00061794 0.0021501"
        rpy="0 0 0" />
      <mass
        value="0.082562" />
      <inertia
        ixx="9.5465E-05"
        ixy="-1.584E-06"
        ixz="-3.3688E-06"
        iyy="0.00012543"
        iyz="1.0963E-07"
        izz="0.00010826" />
    </inertial>
    <visual>
      <origin
        xyz="0 0 0"
        rpy="0 0 0" />
      <geometry>
        <mesh
          filename="package://mk2/meshes/link_7.STL" />
      </geometry>
      <material
        name="">
        <color
          rgba="0.79216 0.81961 0.93333 1" />
      </material>
    </visual>
    <collision>
      <origin
        xyz="0 0 0"
        rpy="0 0 0" />
      <geometry>
        <mesh
          filename="package://mk2/meshes/link_7.STL" />
      </geometry>
    </collision>
  </link>
  <joint
    name="joint_7"
    type="revolute">
    <origin
      xyz="0.0741 0 0"
      rpy="0 0 0" />
    <parent
      link="link_6" />
    <child
      link="link_7" />
    <axis
      xyz="0 0 1" />
    <limit
      lower="-1.57"
      upper="1.57"
      effort="10"
      velocity="2" />
  </joint>
</robot>
