<robot
  name="mk2_torso_description">
  <link
    name="torso_base_link">
    <inertial>
      <origin
        xyz="-0.00018403 0.01103 0.00031125"
        rpy="0 0 0" />
      <mass
        value="0.13049" />
      <inertia
        ixx="0.00020587"
        ixy="1.9521E-07"
        ixz="1.2832E-06"
        iyy="0.00049448"
        iyz="-3.1452E-07"
        izz="0.00032049" />
    </inertial>
    <visual>
      <origin
        xyz="0 0 0"
        rpy="0 0 0" />
      <geometry>
        <mesh
          filename="package://mk2_torso_description/meshes/torso_base_link.STL" />
      </geometry>
      <material
        name="">
        <color
          rgba="0.79216 0.81961 0.93333 1" />
      </material>
    </visual>
    <collision>
      <origin
        xyz="0 0 0"
        rpy="0 0 0" />
      <geometry>
        <mesh
          filename="package://mk2_torso_description/meshes/torso_base_link.STL" />
      </geometry>
    </collision>
  </link>
  <link
    name="torso_yaw_link">
    <inertial>
      <origin
        xyz="-1.0664113596062E-08 0.0628988812468705 2.5325061653577E-09"
        rpy="0 0 0" />
      <mass
        value="0.312439405406118" />
      <inertia
        ixx="0.000737785373037655"
        ixy="5.40470742433578E-11"
        ixz="2.42455236931287E-10"
        iyy="0.00155225038783166"
        iyz="-1.80969158770662E-11"
        izz="0.00179835095301137" />
    </inertial>
    <visual>
      <origin
        xyz="0 0 0"
        rpy="0 0 0" />
      <geometry>
        <mesh
          filename="package://mk2_torso_description/meshes/torso_yaw_link.STL" />
      </geometry>
      <material
        name="">
        <color
          rgba="0.792156862745098 0.819607843137255 0.933333333333333 1" />
      </material>
    </visual>
    <collision>
      <origin
        xyz="0 0 0"
        rpy="0 0 0" />
      <geometry>
        <mesh
          filename="package://mk2_torso_description/meshes/torso_yaw_link.STL" />
      </geometry>
    </collision>
  </link>
  <joint
    name="torso_yaw_joint"
    type="continuous">
    <origin
      xyz="0 0.01 0"
      rpy="0 1.5708 0" />
    <parent
      link="torso_base_link" />
    <child
      link="torso_yaw_link" />
    <axis
      xyz="0 1 0" />
  </joint>
  <link
    name="torso_pitch_link">
    <inertial>
      <origin
        xyz="3.71536021858208E-07 0.0385336088285087 -0.00216821570459846"
        rpy="0 0 0" />
      <mass
        value="0.214939253072605" />
      <inertia
        ixx="0.000647224222348535"
        ixy="4.13577050131344E-09"
        ixz="3.35454012482265E-09"
        iyy="0.000481992877291182"
        iyz="-2.12337487574034E-05"
        izz="0.000508203919522507" />
    </inertial>
    <visual>
      <origin
        xyz="0 0 0"
        rpy="0 0 0" />
      <geometry>
        <mesh
          filename="package://mk2_torso_description/meshes/torso_pitch_link.STL" />
      </geometry>
      <material
        name="">
        <color
          rgba="0.792156862745098 0.819607843137255 0.933333333333333 1" />
      </material>
    </visual>
    <collision>
      <origin
        xyz="0 0 0"
        rpy="0 0 0" />
      <geometry>
        <mesh
          filename="package://mk2_torso_description/meshes/torso_pitch_link.STL" />
      </geometry>
    </collision>
  </link>
  <joint
    name="torso_pitch_joint"
    type="continuous">
    <origin
      xyz="0 0.1172 0"
      rpy="-3.6978E-32 -4.1895E-65 -6.8423E-49" />
    <parent
      link="torso_yaw_link" />
    <child
      link="torso_pitch_link" />
    <axis
      xyz="1 0 0" />
  </joint>
  <link
    name="torso_roll_link">
    <inertial>
      <origin
        xyz="6.7524962994372E-08 0.233960353769095 -0.00500672797843049"
        rpy="0 0 0" />
      <mass
        value="0.293335697547894" />
      <inertia
        ixx="0.00578530758836691"
        ixy="-7.31707616744645E-10"
        ixz="-1.75775564567948E-08"
        iyy="0.000677304130480322"
        iyz="-0.000219289414052924"
        izz="0.00606444160061966" />
    </inertial>
    <visual>
      <origin
        xyz="0 0 0"
        rpy="0 0 0" />
      <geometry>
        <mesh
          filename="package://mk2_torso_description/meshes/torso_roll_link.STL" />
      </geometry>
      <material
        name="">
        <color
          rgba="0.792156862745098 0.819607843137255 0.933333333333333 1" />
      </material>
    </visual>
    <collision>
      <origin
        xyz="0 0 0"
        rpy="0 0 0" />
      <geometry>
        <mesh
          filename="package://mk2_torso_description/meshes/torso_roll_link.STL" />
      </geometry>
    </collision>
  </link>
  <joint
    name="torso_roll_joint"
    type="continuous">
    <origin
      xyz="0 0.08 0"
      rpy="-8.8818E-16 6.7033E-64 1.1632E-47" />
    <parent
      link="torso_pitch_link" />
    <child
      link="torso_roll_link" />
    <axis
      xyz="0 0 1" />
  </joint>
</robot>
