<robot
  name="mk2_arm_description">
  <link
    name="gimbal_base_link">
    <inertial>
      <origin
        xyz="-0.00031125 0.01103 -0.00018403"
        rpy="0 0 0" />
      <mass
        value="0.13049" />
      <inertia
        ixx="0.00032049"
        ixy="3.1452E-07"
        ixz="-1.2832E-06"
        iyy="0.00049448"
        iyz="1.9521E-07"
        izz="0.00020587" />
    </inertial>
    <visual>
      <origin
        xyz="0 0 0"
        rpy="0 0 0" />
      <geometry>
        <mesh
          filename="package://mk2_arm_description/meshes/gimbal_base_link.STL" />
      </geometry>
      <material
        name="">
        <color
          rgba="0.79216 0.81961 0.93333 1" />
      </material>
    </visual>
    <collision>
      <origin
        xyz="0 0 0"
        rpy="0 0 0" />
      <geometry>
        <mesh
          filename="package://mk2_arm_description/meshes/gimbal_base_link.STL" />
      </geometry>
    </collision>
  </link>
  <link
    name="gimbal_yaw_Link">
    <inertial>
      <origin
        xyz="0 0.052199 0"
        rpy="0 0 0" />
      <mass
        value="0.31244" />
      <inertia
        ixx="0.00073779"
        ixy="0"
        ixz="0"
        iyy="0.0015523"
        iyz="0"
        izz="0.0017984" />
    </inertial>
    <visual>
      <origin
        xyz="0 0 0"
        rpy="0 0 0" />
      <geometry>
        <mesh
          filename="package://mk2_arm_description/meshes/gimbal_yaw_Link.STL" />
      </geometry>
      <material
        name="">
        <color
          rgba="0.79216 0.81961 0.93333 1" />
      </material>
    </visual>
    <collision>
      <origin
        xyz="0 0 0"
        rpy="0 0 0" />
      <geometry>
        <mesh
          filename="package://mk2_arm_description/meshes/gimbal_yaw_Link.STL" />
      </geometry>
    </collision>
  </link>
  <joint
    name="gimbal_yaw_joint"
    type="continuous">
    <origin
      xyz="0 0 0.0207"
      rpy="1.5708 0 1.5894" />
    <parent
      link="gimbal_base_link" />
    <child
      link="gimbal_yaw_Link" />
    <axis
      xyz="0 -1 0" />
  </joint>
  <link
    name="gimbal_pitch_Link">
    <inertial>
      <origin
        xyz="3.7236E-07 0.038534 -0.0021682"
        rpy="0 0 0" />
      <mass
        value="0.21494" />
      <inertia
        ixx="0.00064722"
        ixy="4.1387E-09"
        ixz="3.3453E-09"
        iyy="0.00048199"
        iyz="-2.1234E-05"
        izz="0.0005082" />
    </inertial>
    <visual>
      <origin
        xyz="0 0 0"
        rpy="0 0 0" />
      <geometry>
        <mesh
          filename="package://mk2_arm_description/meshes/gimbal_pitch_Link.STL" />
      </geometry>
      <material
        name="">
        <color
          rgba="0.79216 0.81961 0.93333 1" />
      </material>
    </visual>
    <collision>
      <origin
        xyz="0 0 0"
        rpy="0 0 0" />
      <geometry>
        <mesh
          filename="package://mk2_arm_description/meshes/gimbal_pitch_Link.STL" />
      </geometry>
    </collision>
  </link>
  <joint
    name="gimbal_pitch_joint"
    type="continuous">
    <origin
      xyz="0 0.1065 0"
      rpy="0.015488 0 0" />
    <parent
      link="gimbal_yaw_Link" />
    <child
      link="gimbal_pitch_Link" />
    <axis
      xyz="1 0 0" />
  </joint>
  <link
    name="gimbal_roll_Link">
    <inertial>
      <origin
        xyz="7.9412E-08 0.23396 -0.0050067"
        rpy="0 0 0" />
      <mass
        value="0.29334" />
      <inertia
        ixx="0.0057853"
        ixy="0"
        ixz="-1.7452E-08"
        iyy="0.0006773"
        iyz="-0.00021929"
        izz="0.0060644" />
    </inertial>
    <visual>
      <origin
        xyz="0 0 0"
        rpy="0 0 0" />
      <geometry>
        <mesh
          filename="package://mk2_arm_description/meshes/gimbal_roll_Link.STL" />
      </geometry>
      <material
        name="">
        <color
          rgba="0.79216 0.81961 0.93333 1" />
      </material>
    </visual>
    <collision>
      <origin
        xyz="0 0 0"
        rpy="0 0 0" />
      <geometry>
        <mesh
          filename="package://mk2_arm_description/meshes/gimbal_roll_Link.STL" />
      </geometry>
    </collision>
  </link>
  <joint
    name="gimbal_roll_joint"
    type="continuous">
    <origin
      xyz="0 0.08 0"
      rpy="0 0 0.033714" />
    <parent
      link="gimbal_pitch_Link" />
    <child
      link="gimbal_roll_Link" />
    <axis
      xyz="0 0 -1" />
  </joint>
</robot>