<?xml version="1.0"?>

<!-- XML namespaces -->

<robot xmlns:sensor="http://playerstage.sourceforge.net/gazebo/xmlschema/#sensor"
       xmlns:controller="http://playerstage.sourceforge.net/gazebo/xmlschema/#controller"
       xmlns:interface="http://playerstage.sourceforge.net/gazebo/xmlschema/#interface"
       xmlns:xacro="http://ros.org/wiki/xacro" 
	   name="arms">
    
 	<!-- ============================   Body   ============================ -->

	<link name="gantry_base_link" >
	  <inertial>
            <mass value="0.030" />
            <origin xyz="0 0 0" rpy="0 0 0" />
            <inertia ixx="1.0" ixy="0" ixz="0"
                     iyy="1.0" iyz="0" 
                     izz="1.0" />
          </inertial>
          <visual>
            <origin xyz="0 0 0" rpy="0 0 0" />
            <geometry>
              <mesh filename="package://mmUAV_description/meshes/Gantry.stl"/>
            </geometry>
	    <material name="black">
              <color rgba="0.1 0.1 0.1 0.9"/>
	    </material>
	  </visual>
        </link>

	<!-- =================== Gantry X-Y-Z ============================= -->

	<link name="gantry_x_joint_link" >
	  <inertial>
            <mass value="0.030" />
            <origin xyz="0 0 0" rpy="0 0 0" />
            <inertia ixx="1.0" ixy="0" ixz="0"
                     iyy="1.0" iyz="0" 
                     izz="1.0" />
          </inertial>
          <visual>
            <origin xyz="0 0 0" rpy="0 0 0" />
            <geometry>
              <mesh filename="package://mmUAV_description/meshes/Gantry_x-axis.stl"/>
            </geometry>
	    <material name="blue">
	        <color rgba="0 0 .8 1"/>
	    </material>
	  </visual>
        </link>

	<link name="gantry_y_joint_link" >
	  <inertial>
            <mass value="0.030" />
            <origin xyz="0 0 0" rpy="0 0 0" />
            <inertia ixx="1.0" ixy="0" ixz="0"
                     iyy="1.0" iyz="0" 
                     izz="1.0" />
          </inertial>
          <visual>
            <origin xyz="0 0 0" rpy="0 0 0" />
            <geometry>
              <mesh filename="package://mmUAV_description/meshes/Gantry_y-axis.stl"/>
            </geometry>
	    <material name="black">
              <color rgba="0.1 0.1 0.1 0.9"/>
	    </material>
	  </visual>
        </link>

	<link name="gantry_z_joint_link" >
	  <inertial>
            <mass value="0.030" />
            <origin xyz="0 0 0" rpy="0 0 0" />
            <inertia ixx="1.0" ixy="0" ixz="0"
                     iyy="1.0" iyz="0" 
                     izz="1.0" />
          </inertial>
          <visual>
            <origin xyz="0 0 0" rpy="0 0 3.14" />
            <geometry>
              <mesh filename="package://mmUAV_description/meshes/Gantry_z-axis.stl"/>
            </geometry>
	    <material name="blue">
              <color rgba="0 0 .8 1"/>
	    </material>
	  </visual>
        </link>

	<!-- =================== Gantry Yaw-Pitch-Roll ============================= -->

	<link name="gantry_yaw_joint_link" >
	  <inertial>
            <mass value="0.030" />
            <origin xyz="0 0 0" rpy="0 0 0" />
            <inertia ixx="1.0" ixy="0" ixz="0"
                     iyy="1.0" iyz="0" 
                     izz="1.0" />
          </inertial>
          <visual>
            <origin xyz="0 0 0" rpy="0 0 1.54" />
            <geometry>
              <mesh filename="package://mmUAV_description/meshes/Gantry_yaw.stl"/>
            </geometry>
	    <material name="black">
              <color rgba="0.1 0.1 0.1 0.9"/>
	    </material>
	  </visual>
        </link>

	<link name="gantry_pitch_joint_link" >
	  <inertial>
            <mass value="0.030" />
            <origin xyz="0 0 0" rpy="0 0 0" />
            <inertia ixx="1.0" ixy="0" ixz="0"
                     iyy="1.0" iyz="0" 
                     izz="1.0" />
          </inertial>
          <visual>
            <origin xyz="0 0 0" rpy="1.57 0 3.14" />
            <geometry>
              <mesh filename="package://mmUAV_description/meshes/Gantry_pitch.stl"/>
            </geometry>
	    <material name="blue">
              <color rgba="0 0 .8 1"/>
	    </material>
	  </visual>
        </link>

	<link name="gantry_roll_joint_link" >
          <inertial>
            <mass value="0.030" />
            <origin xyz="0 0 0" rpy="0 0 0" />
            <inertia ixx="1.0" ixy="0" ixz="0"
                     iyy="1.0" iyz="0" 
                     izz="1.0" />
          </inertial>
          <visual>
            <origin xyz="0.05 0.07 -0.013" rpy="-1.57 0 1.57" />
            <geometry>
              <mesh filename="package://mmUAV_description/meshes/Gaui_500_baseplate_7-31-2012.STL"/>
            </geometry>
	    <material name="black">
              <color rgba="0.1 0.1 0.1 0.9"/>
	    </material>
	  </visual>
        </link>

	<!-- =================== Right Arm ============================= -->

	<link name="right_baseplate_servo_link" >
          <inertial>
            <mass value="0.030" />
            <origin xyz="0 0 0" rpy="0 0 0" />
            <inertia ixx="1.0" ixy="0" ixz="0"
                       iyy="1.0" iyz="0" 
                       izz="1.0" />
          </inertial>
          <visual>
            <origin xyz="0 0 0" rpy="0 0 0" />
            <geometry>
              <mesh filename="package://mmUAV_description/meshes/hs-85bb_mighty_feather.stl"/>
            </geometry>
	    <material name="black">
	      <color rgba="0.1 0.1 0.1 0.9"/>
	    </material>
          </visual>
        </link>


	<link name="right_shoulder_roll_link" >
          <inertial>
            <mass value="0.030" />
            <origin xyz="0 0 0" rpy="0 0 0" />
            <inertia ixx="1.0" ixy="0" ixz="0"
                       iyy="1.0" iyz="0" 
                       izz="1.0" />
          </inertial>
          <visual>
            <origin xyz="0 0 0" rpy="0 0 0" />
            <geometry>
              <mesh filename="package://mmUAV_description/meshes/ServoMount_3c.stl"/>
            </geometry>
	    <material name="blue">
	      <color rgba="0 0 .8 1"/>
	    </material>
          </visual>
        </link>


        <link name="right_shoulder_pitch_link" >
          <inertial>
            <mass value="0.030" />
            <origin xyz="0 0 0" rpy="0 0 0" />
            <inertia ixx="1.0" ixy="0" ixz="0"
                     iyy="1.0" iyz="0" 
                     izz="1.0" />
          </inertial>
          <visual>
            <origin xyz="0 0 0" rpy="0 0 0" />
            <geometry>
              <mesh filename="package://mmUAV_description/meshes/ServoMount_3b.stl"/>
            </geometry>
    	    <material name="black">
              <color rgba="0.1 0.1 0.1 0.9"/>
	    </material>
          </visual>
        </link> 

        <link name="right_elbow_roll_link" >
          <inertial>
            <mass value="0.030" />
            <origin xyz="0 0 0" rpy="0 0 0" />
            <inertia ixx="1.0" ixy="0" ixz="0"
                     iyy="1.0" iyz="0" 
                     izz="1.0" />
          </inertial>
          <visual>
            <origin xyz="0 0 0" rpy="0 0 0" />
            <geometry>
              <mesh filename="package://mmUAV_description/meshes/ServoMount_3a.stl"/>
            </geometry>
    	    <material name="blue">
	        <color rgba="0 0 .8 1"/>
	    </material>
          </visual>
        </link> 

        <link name="right_elbow_pitch_link" >
          <inertial>
            <mass value="0.030" />
            <origin xyz="0 0 0" rpy="0 0 0" />
            <inertia ixx="1.0" ixy="0" ixz="0"
                     iyy="1.0" iyz="0" 
                     izz="1.0" />
          </inertial>
          <visual>
            <origin xyz="0 0 0" rpy="0 0 0" />
            <geometry>
              <mesh filename="package://mmUAV_description/meshes/FingerTip_v2012.STL"/>
            </geometry>
    	    <material name="black">
              <color rgba="0.1 0.1 0.1 0.9"/>
	    </material>
          </visual>
        </link> 

	<!-- =================== Left Arm ============================= -->

	<link name="left_baseplate_servo_link" >
          <inertial>
            <mass value="0.030" />
            <origin xyz="0 0 0" rpy="0 0 0" />
            <inertia ixx="1.0" ixy="0" ixz="0"
                       iyy="1.0" iyz="0" 
                       izz="1.0" />
          </inertial>
          <visual>
            <origin xyz="0 0 0" rpy="0 0 0" />
            <geometry>
              <mesh filename="package://mmUAV_description/meshes/baseplate_servo.stl"/>
            </geometry>
	    <material name="black">
	      <color rgba="0.1 0.1 0.1 0.9"/>
	    </material>
          </visual>
        </link>


	<link name="left_shoulder_roll_link" >
          <inertial>
            <mass value="0.030" />
            <origin xyz="0 0 0" rpy="0 0 0" />
            <inertia ixx="1.0" ixy="0" ixz="0"
                       iyy="1.0" iyz="0" 
                       izz="1.0" />
          </inertial>
          <visual>
            <origin xyz="0 0 0" rpy="0 0 0" />
            <geometry>
              <mesh filename="package://mmUAV_description/meshes/ServoMount_3c.stl"/>
            </geometry>
 	    <material name="blue">
	      <color rgba="0 0 .8 1"/>
	    </material>
          </visual>
        </link>

        <link name="left_shoulder_pitch_link" >
          <inertial>
            <mass value="0.030" />
            <origin xyz="0 0 0" rpy="0 0 0" />
            <inertia ixx="1.0" ixy="0" ixz="0"  
                     iyy="1.0" iyz="0" 
                     izz="1.0" />
          </inertial>
          <visual>
            <origin xyz="0 0 0" rpy="0 0 0" />
            <geometry>
              <mesh filename="package://mmUAV_description/meshes/ServoMount_3b.stl"/>
            </geometry>
    	    <material name="black">
              <color rgba="0.1 0.1 0.1 0.9"/>
	    </material>
          </visual>
        </link> 

        <link name="left_elbow_roll_link" >
          <inertial>
            <mass value="0.030" />
            <origin xyz="0 0 0" rpy="0 0 0" />
            <inertia ixx="1.0" ixy="0" ixz="0"
                     iyy="1.0" iyz="0" 
                     izz="1.0" />
          </inertial>
          <visual>
            <origin xyz="0 0 0" rpy="0 0 0" />
            <geometry>
              <mesh filename="package://mmUAV_description/meshes/ServoMount_3a.stl"/>
            </geometry>
    	    <material name="blue">
	        <color rgba="0 0 .8 1"/>
	    </material>
          </visual>
        </link> 

        <link name="left_elbow_pitch_link" >
          <inertial>
            <mass value="0.030" />
            <origin xyz="0 0 0" rpy="0 0 0" />
            <inertia ixx="1.0" ixy="0" ixz="0"
                     iyy="1.0" iyz="0" 
                     izz="1.0" />
          </inertial>
          <visual>
            <origin xyz="0 0 0" rpy="0 0 0" />
            <geometry>
              <mesh filename="package://mmUAV_description/meshes/FingerTip_v2012.STL"/>
            </geometry>
    	    <material name="black">
              <color rgba="0.1 0.1 0.1 0.9"/>
	    </material>
          </visual>
        </link> 

	<!-- =================== Joint Definitions ======================== -->

	<!-- =================== Gantry X-Y-Z ============================= -->

	<joint name="gantry_x_joint" type="prismatic">
    	<parent link="gantry_base_link" />
    	<child link="gantry_x_joint_link" />
    	<origin xyz="0.178 0 0.737" rpy="0 0 0" />
    	<axis xyz="1 0 0" />
    	<limit lower="0" upper="0.66" effort="10" velocity="3" />
	</joint>

	<joint name="gantry_y_joint" type="prismatic">
    	<parent link="gantry_x_joint_link" />
    	<child link="gantry_y_joint_link" />
    	<origin xyz="0 0.394 0.025" rpy="0 0 0" />
    	<axis xyz="0 1 0" />
    	<limit lower="-0.227" upper="0.227" effort="10" velocity="3" />
	</joint>

	<joint name="gantry_z_joint" type="prismatic">
    	<parent link="gantry_y_joint_link" />
    	<child link="gantry_z_joint_link" />
    	<origin xyz="0 0.003 -0.279 " rpy="0 0 0" />
    	<axis xyz="0 0 1" />
    	<limit lower="-0.1" upper="0.1" effort="10" velocity="3" />
	</joint>

	<!-- =================== Gantry Yaw-Pitch-Roll ==================== -->

	<joint name="gantry_yaw_joint" type="revolute">
    	<parent link="gantry_z_joint_link" />
    	<child link="gantry_yaw_joint_link" />
    	<origin xyz="0 0 0" rpy="0 0 0" />
    	<axis xyz="0 0 1" />
    	<limit lower="-1.56" upper="1.56" effort="10" velocity="3" />
	</joint>

	<joint name="gantry_pitch_joint" type="revolute">
    	<parent link="gantry_yaw_joint_link" />
    	<child link="gantry_pitch_joint_link" />
    	<origin xyz="0 0 -0.025" rpy="0 0 0" />
    	<axis xyz="0 1 0" />
    	<limit lower="-0.05" upper="0.05" effort="10" velocity="3" />
	</joint>

	<joint name="gantry_roll_joint" type="revolute">
    	<parent link="gantry_pitch_joint_link" />
    	<child link="gantry_roll_joint_link" />
   	<origin xyz="-0.033 0 0" rpy="0 0 0" /> 
    	<axis xyz="1 0 0" />
    	<limit lower="-0.05" upper="0.05" effort="10" velocity="3" />
	</joint>

	<!-- =================== Rigth Arm ==================== -->

	<joint name="right_baseplate_servo_joint" type="revolute">
	<parent link="gantry_roll_joint_link" />
    	<child link="right_baseplate_servo_link" />
        <origin xyz="0.01 -0.04 -0.053" rpy="1.57 0 1.57" />
        <limit lower="-0.0001" upper="0.0001" effort="10" velocity="3" />
        <axis xyz="0 0 1" />
    	<dynamics damping="0.0"/>
	</joint>	

	<joint name="right_shoulder_roll_joint" type="revolute">
	<parent link="gantry_roll_joint_link" />
    	<child link="right_shoulder_roll_link" />
        <origin xyz="0.03 -0.035 -0.047" rpy="0 0 1.57" />
        <limit lower="-1.57" upper="1.57" effort="10" velocity="3" />
        <axis xyz="0 1 0" />
    	<dynamics damping="0.0"/>
	</joint>

	<joint name="right_shoulder_pitch_joint" type="revolute">
	<parent link="right_shoulder_roll_link" />
    	<child link="right_shoulder_pitch_link" />
        <origin xyz="-0.0001 0.002 -0.0375" rpy="0 0 1.57" />
        <limit lower="-1.57" upper="1.57" effort="10" velocity="3" />
        <axis xyz="0 1 0" />
    	<dynamics damping="0.0"/>
	</joint>

	<joint name="right_elbow_roll_joint" type="revolute">
	<parent link="right_shoulder_pitch_link" />
    	<child link="right_elbow_roll_link" />
        <origin xyz="-0.0005 0.0005 -0.038" rpy="0 0 -1.57" />
        <limit lower="-1.57" upper="1.57" effort="10" velocity="3" />
        <axis xyz="0 1 0" />
    	<dynamics damping="0.0"/>
	</joint>

	<joint name="right_elbow_pitch_joint" type="revolute">
	<parent link="right_elbow_roll_link" />
    	<child link="right_elbow_pitch_link" />
        <origin xyz="-0.0008 0.0001 -0.0376" rpy="0 0 3.14" />
        <limit lower="-1.57" upper="1.57" effort="10" velocity="3" />
        <axis xyz="1 0 0" />
    	<dynamics damping="0.0"/>
	</joint>

	<!-- =================== Left Arm ==================== -->

	<joint name="left_baseplate_servo_joint" type="revolute">
	<parent link="gantry_roll_joint_link" />
    	<child link="left_baseplate_servo_link" />
        <origin xyz="0.016 0.042 -0.058" rpy="-1.57 3.14 1.57" />
        <limit lower="-1.57" upper="1.57" effort="10" velocity="3" />
        <axis xyz="0 1 0" />
    	<dynamics damping="0.0"/>
	</joint>	

	<joint name="left_shoulder_roll_joint" type="revolute">
	<parent link="gantry_roll_joint_link" />
    	<child link="left_shoulder_roll_link" />
        <origin xyz="0.027 0.036 -0.046" rpy="0 0 -1.57" />
        <limit lower="-1.57" upper="1.57" effort="10" velocity="3" />
        <axis xyz="0 1 0" />
    	<dynamics damping="0.0"/>
	</joint>

	<joint name="left_shoulder_pitch_joint" type="revolute">
	<parent link="left_shoulder_roll_link" />
    	<child link="left_shoulder_pitch_link" />
        <origin xyz="-0.0001 0.002 -0.0375" rpy="0 0 1.57" />
        <limit lower="-1.57" upper="1.57" effort="10" velocity="3" />
        <axis xyz="0 1 0" />
    	<dynamics damping="0.0"/>
	</joint>

	<joint name="left_elbow_roll_joint" type="revolute">
	<parent link="left_shoulder_pitch_link" />
    	<child link="left_elbow_roll_link" />
        <origin xyz="-0.0005 0.0005 -0.038" rpy="0 0 -1.57" />
        <limit lower="-1.57" upper="1.57" effort="10" velocity="3" />
        <axis xyz="0 1 0" />
    	<dynamics damping="0.0"/>
	</joint>

	<joint name="left_elbow_pitch_joint" type="revolute">
	<parent link="left_elbow_roll_link" />
    	<child link="left_elbow_pitch_link" />
        <origin xyz="-0.0008 0.0001 -0.0376" rpy="0 0 -3.14" />
        <limit lower="-1.57" upper="1.57" effort="10" velocity="3" />
        <axis xyz="1 0 0" />
    	<dynamics damping="0.0"/>
	</joint>

	<!-- =================== Gazebo ==================== -->

	<gazebo reference="mmUAV">
  	</gazebo>

</robot>

