<robot
  name="mk2_controller">
  <link
    name="gantry_gimbal_base_link">
    <inertial>
      <origin
        xyz="0.000473619551376741 -0.00055288321950696 -0.0593340384740967"
        rpy="0 0 0" />
      <mass
        value="0.356270706990662" />
      <inertia
        ixx="0.00225643771000187"
        ixy="1.16412359258895E-06"
        ixz="-1.10566802868083E-05"
        iyy="0.00202518994082258"
        iyz="1.0481224651543E-05"
        izz="0.000705634387677061" />
    </inertial>
    <visual>
      <origin
        xyz="0 0 0"
        rpy="0 0 0" />
      <geometry>
        <mesh
          filename="package://mk2_controller/meshes/gantry_gimbal_base_link.STL" />
      </geometry>
      <material
        name="">
        <color
          rgba="0.752941176470588 0.752941176470588 0.752941176470588 1" />
      </material>
    </visual>
    <collision>
      <origin
        xyz="0 0 0"
        rpy="0 0 0" />
      <geometry>
        <mesh
          filename="package://mk2_controller/meshes/gantry_gimbal_base_link.STL" />
      </geometry>
    </collision>
  </link>
  <link
    name="gimbal_yaw_link">
    <inertial>
      <origin
        xyz="-1.06665506966198E-08 0.0521988814118078 2.53314634033474E-09"
        rpy="0 0 0" />
      <mass
        value="0.312439397659762" />
      <inertia
        ixx="0.000737785371947909"
        ixy="5.40589866324287E-11"
        ixz="2.53315092931346E-10"
        iyy="0.00155225036595944"
        iyz="-1.81054329997615E-11"
        izz="0.00179835093178404" />
    </inertial>
    <visual>
      <origin
        xyz="0 0 0"
        rpy="0 0 0" />
      <geometry>
        <mesh
          filename="package://mk2_controller/meshes/gimbal_yaw_link.STL" />
      </geometry>
      <material
        name="">
        <color
          rgba="0.792156862745098 0.819607843137255 0.933333333333333 1" />
      </material>
    </visual>
    <collision>
      <origin
        xyz="0 0 0"
        rpy="0 0 0" />
      <geometry>
        <mesh
          filename="package://mk2_controller/meshes/gimbal_yaw_link.STL" />
      </geometry>
    </collision>
  </link>
  <joint
    name="gimbal_yaw_joint"
    type="continuous">
    <origin
      xyz="0 0 0.0207"
      rpy="1.5708 -5.6772E-17 1.5894" />
    <parent
      link="gantry_gimbal_base_link" />
    <child
      link="gimbal_yaw_link" />
    <axis
      xyz="0 -1 0" />
  </joint>
  <link
    name="gimbal_pitch_link">
    <inertial>
      <origin
        xyz="3.72542411790654E-07 0.0385336076254783 -0.00216821775220596"
        rpy="0 0 0" />
      <mass
        value="0.214939217277683" />
      <inertia
        ixx="0.000647224206654954"
        ixy="4.13857175925613E-09"
        ixz="3.34682857690363E-09"
        iyy="0.000481992847108144"
        iyz="-2.12337392548007E-05"
        izz="0.000508203899610375" />
    </inertial>
    <visual>
      <origin
        xyz="0 0 0"
        rpy="0 0 0" />
      <geometry>
        <mesh
          filename="package://mk2_controller/meshes/gimbal_pitch_link.STL" />
      </geometry>
      <material
        name="">
        <color
          rgba="0.792156862745098 0.819607843137255 0.933333333333333 1" />
      </material>
    </visual>
    <collision>
      <origin
        xyz="0 0 0"
        rpy="0 0 0" />
      <geometry>
        <mesh
          filename="package://mk2_controller/meshes/gimbal_pitch_link.STL" />
      </geometry>
    </collision>
  </link>
  <joint
    name="gimbal_pitch_joint"
    type="continuous">
    <origin
      xyz="0 0.1065 0"
      rpy="0.015488 1.1768E-14 -3.0626E-20" />
    <parent
      link="gimbal_yaw_link" />
    <child
      link="gimbal_pitch_link" />
    <axis
      xyz="1 0 0" />
  </joint>
  <link
    name="gimbal_roll_link">
    <inertial>
      <origin
        xyz="7.94122340065304E-08 0.233960269936441 -0.0050066970043719"
        rpy="0 0 0" />
      <mass
        value="0.29333576544646" />
      <inertia
        ixx="0.00578531062012239"
        ixy="-3.00216964747404E-10"
        ixz="-1.74522595137983E-08"
        iyy="0.000677304177339112"
        iyz="-0.000219289260917761"
        izz="0.00606444384166286" />
    </inertial>
    <visual>
      <origin
        xyz="0 0 0"
        rpy="0 0 0" />
      <geometry>
        <mesh
          filename="package://mk2_controller/meshes/gimbal_roll_link.STL" />
      </geometry>
      <material
        name="">
        <color
          rgba="0.792156862745098 0.819607843137255 0.933333333333333 1" />
      </material>
    </visual>
    <collision>
      <origin
        xyz="0 0 0"
        rpy="0 0 0" />
      <geometry>
        <mesh
          filename="package://mk2_controller/meshes/gimbal_roll_link.STL" />
      </geometry>
    </collision>
  </link>
  <joint
    name="gimbal_roll_joint"
    type="continuous">
    <origin
      xyz="0 0.08 0"
      rpy="-2.3375E-16 -1.707E-15 0.033714" />
    <parent
      link="gimbal_pitch_link" />
    <child
      link="gimbal_roll_link" />
    <axis
      xyz="0 0 -1" />
  </joint>
</robot>