<?xml version="1.0" ?>
<!-- =================================================================================== -->
<!-- |    This document was autogenerated by xacro from mm_uav.urdf.xacro              | -->
<!-- |    EDITING THIS FILE BY HAND IS NOT RECOMMENDED                                 | -->
<!-- =================================================================================== -->
<!-- XML namespaces -->
<robot name="mm_uav" xmlns:controller="http://playerstage.sourceforge.net/gazebo/xmlschema/#controller" xmlns:interface="http://playerstage.sourceforge.net/gazebo/xmlschema/#interface" xmlns:sensor="http://playerstage.sourceforge.net/gazebo/xmlschema/#sensor" xmlns:xacro="http://ros.org/wiki/xacro">
  <!-- ============================   Body   ============================ -->
  <link name="gantry_base_link"/>
  <link name="gantry_x_joint_link"/>
  <link name="gantry_y_joint_link"/>
  <link name="gantry_z_joint_link"/>
  <link name="gantry_yaw_joint_link"/>
  <link name="gantry_pitch_joint_link"/>
  <link name="gantry_roll_joint_link">
    <inertial>
      <mass value="0.030"/>
      <origin rpy="0 0 0" xyz="0 0 0"/>
      <inertia ixx="1.0" ixy="0" ixz="0" iyy="1.0" iyz="0" izz="1.0"/>
    </inertial>
    <visual>
      <origin rpy="1.54 0 1.54" xyz="0.025 0 -0.035"/>
      <geometry>
        <mesh filename="package://mm_uav_description/meshes/gantry_roll_joint_link.stl"/>
      </geometry>
      <material name="black">
        <color rgba="0.1 0.1 0.1 0.9"/>
      </material>
    </visual>
  </link>
  <link name="right_shoulder_yaw_link">
    <inertial>
      <mass value="0.030"/>
      <origin rpy="0 0 0" xyz="0 0 0"/>
      <inertia ixx="1.0" ixy="0" ixz="0" iyy="1.0" iyz="0" izz="1.0"/>
    </inertial>
    <visual>
      <origin rpy="0 0 0" xyz="0 0 0"/>
      <geometry>
        <mesh filename="package://mm_uav_description/meshes/right_shoulder_yaw_link.stl"/>
      </geometry>
      <material name="blue">
        <color rgba="0 0 .8 1"/>
      </material>
    </visual>
  </link>
  <link name="right_shoulder_pitch_link">
    <inertial>
      <mass value="0.030"/>
      <origin rpy="0 0 0" xyz="0 0 0"/>
      <inertia ixx="1.0" ixy="0" ixz="0" iyy="1.0" iyz="0" izz="1.0"/>
    </inertial>
    <visual>
      <origin rpy="0 0 0" xyz="0 0 0"/>
      <geometry>
        <mesh filename="package://mm_uav_description/meshes/right_shoulder_pitch_link.stl"/>
      </geometry>
      <material name="black">
        <color rgba="0.1 0.1 0.1 0.9"/>
      </material>
    </visual>
  </link>
  <link name="right_shoulder_roll_link">
    <inertial>
      <mass value="0.030"/>
      <origin rpy="0 0 0" xyz="0 0 0"/>
      <inertia ixx="1.0" ixy="0" ixz="0" iyy="1.0" iyz="0" izz="1.0"/>
    </inertial>
    <visual>
      <origin rpy="0 0 0" xyz="0 0 0"/>
      <geometry>
        <mesh filename="package://mm_uav_description/meshes/right_shoulder_roll_link.stl"/>
      </geometry>
      <material name="blue">
        <color rgba="0 0 .8 1"/>
      </material>
    </visual>
  </link>
  <link name="right_elbow_pitch_link">
    <inertial>
      <mass value="0.030"/>
      <origin rpy="0 0 0" xyz="0 0 0"/>
      <inertia ixx="1.0" ixy="0" ixz="0" iyy="1.0" iyz="0" izz="1.0"/>
    </inertial>
    <visual>
      <origin rpy="0 0 0" xyz="0 0 0"/>
      <geometry>
        <mesh filename="package://mm_uav_description/meshes/right_elbow_pitch_link.stl"/>
      </geometry>
      <material name="black">
        <color rgba="0.1 0.1 0.1 0.9"/>
      </material>
    </visual>
  </link>
  <link name="right_manipulator_link">
    <inertial>
      <mass value="0.030"/>
      <origin rpy="0 0 0" xyz="0 0 0"/>
      <inertia ixx="1.0" ixy="0" ixz="0" iyy="1.0" iyz="0" izz="1.0"/>
    </inertial>
    <visual>
      <origin rpy="1.54 0 0" xyz="0 -0.03 0"/>
      <geometry>
        <mesh filename="package://mm_uav_description/meshes/right_manipulator_link.stl"/>
      </geometry>
      <material name="blue">
        <color rgba="0 0 .8 1"/>
      </material>
    </visual>
  </link>
  <link name="left_shoulder_yaw_link"/>
  <link name="left_shoulder_pitch_link"/>
  <link name="left_shoulder_roll_link"/>
  <link name="left_elbow_pitch_link"/>
  <link name="left_manipulator_link"/>
  <!-- =================== Joint Definitions ======================== -->
  <!-- =================== Gantry X-Y-Z ============================= -->
  <joint name="gantry_x_joint" type="prismatic">
    <parent link="gantry_base_link"/>
    <child link="gantry_x_joint_link"/>
    <origin rpy="0 0 0" xyz="0.483 0.356 0.757"/>
    <axis xyz="1 0 0"/>
    <limit effort="10" lower="-0.381" upper="0.381" velocity="3"/>
  </joint>
  <joint name="gantry_y_joint" type="prismatic">
    <parent link="gantry_x_joint_link"/>
    <child link="gantry_y_joint_link"/>
    <origin rpy="0 0 0" xyz="0 0 0.038"/>
    <axis xyz="0 1 0"/>
    <limit effort="10" lower="-0.254" upper="0.254" velocity="3"/>
  </joint>
  <joint name="gantry_z_joint" type="prismatic">
    <parent link="gantry_y_joint_link"/>
    <child link="gantry_z_joint_link"/>
    <origin rpy="0 0 0" xyz="0 0 -0.318"/>
    <axis xyz="0 0 1"/>
    <limit effort="10" lower="-0.102" upper="0.127" velocity="3"/>
  </joint>
  <!-- =================== Gantry Yaw-Pitch-Roll ==================== -->
  <joint name="gantry_yaw_joint" type="revolute">
    <parent link="gantry_z_joint_link"/>
    <child link="gantry_yaw_joint_link"/>
    <origin rpy="0 0 0" xyz="0 0 -0.051"/>
    <axis xyz="0 0 1"/>
    <limit effort="10" lower="-3.14" upper="3.14" velocity="3"/>
  </joint>
  <joint name="gantry_pitch_joint" type="revolute">
    <parent link="gantry_yaw_joint_link"/>
    <child link="gantry_pitch_joint_link"/>
    <origin rpy="0 0 0" xyz="0 0 -0.025"/>
    <axis xyz="0 1 0"/>
    <limit effort="10" lower="-1" upper="1" velocity="3"/>
  </joint>
  <joint name="gantry_roll_joint" type="revolute">
    <parent link="gantry_pitch_joint_link"/>
    <child link="gantry_roll_joint_link"/>
    <origin rpy="0 0 0" xyz="-0.033 0 0"/>
    <axis xyz="1 0 0"/>
    <limit effort="10" lower="-1" upper="1" velocity="3"/>
  </joint>
  <!-- =================== Rigth Arm ==================== -->
  <joint name="right_shoulder_yaw_joint" type="revolute">
    <parent link="gantry_roll_joint_link"/>
    <child link="right_shoulder_yaw_link"/>
    <origin rpy="0 0 0" xyz="0.025 -0.130 -0.07"/>
    <limit effort="10" lower="-3.14" upper="3.14" velocity="3"/>
    <axis xyz="0 0 1"/>
    <dynamics damping="0.0"/>
  </joint>
  <joint name="right_shoulder_pitch_joint" type="revolute">
    <parent link="right_shoulder_yaw_link"/>
    <child link="right_shoulder_pitch_link"/>
    <origin rpy="0 0 0" xyz="0 0 -0.027"/>
    <limit effort="10" lower="-1.54" upper="1.54" velocity="3"/>
    <axis xyz="1 0 0"/>
    <dynamics damping="0.0"/>
  </joint>
  <joint name="right_shoulder_roll_joint" type="revolute">
    <parent link="right_shoulder_pitch_link"/>
    <child link="right_shoulder_roll_link"/>
    <limit effort="10" lower="-3.14" upper="3.14" velocity="3"/>
    <origin rpy="0 0 0" xyz="0 0 -0.082"/>
    <axis xyz="0 0 1"/>
    <dynamics damping="0.0"/>
  </joint>
  <joint name="right_elbow_pitch_joint" type="revolute">
    <parent link="right_shoulder_roll_link"/>
    <child link="right_elbow_pitch_link"/>
    <origin rpy="0 0 0" xyz="0 0 -0.027"/>
    <limit effort="10" lower="-1.54" upper="1.54" velocity="3"/>
    <axis xyz="1 0 0"/>
    <dynamics damping="0.0"/>
  </joint>
  <joint name="right_manipulator_joint" type="revolute">
    <parent link="right_elbow_pitch_link"/>
    <child link="right_manipulator_link"/>
    <origin rpy="0 0 0" xyz="0 -0.017 -0.063"/>
    <limit effort="10" lower="-0.5" upper="0.5" velocity="3"/>
    <axis xyz="1 0 0"/>
    <dynamics damping="0.0"/>
  </joint>
  <!-- =================== Left Arm ==================== -->
  <joint name="left_shoulder_yaw_joint" type="revolute">
    <parent link="gantry_roll_joint_link"/>
    <child link="left_shoulder_yaw_link"/>
    <origin rpy="0 0 0" xyz="0.025 0.130 -0.07"/>
    <limit effort="10" lower="-3.14" upper="3.14" velocity="3"/>
    <axis xyz="0 0 1"/>
    <dynamics damping="0.0"/>
  </joint>
  <joint name="left_shoulder_pitch_joint" type="revolute">
    <parent link="left_shoulder_yaw_link"/>
    <child link="left_shoulder_pitch_link"/>
    <origin rpy="0 0 0" xyz="0 0 -0.027"/>
    <limit effort="10" lower="-1.54" upper="1.54" velocity="3"/>
    <axis xyz="1 0 0"/>
    <dynamics damping="0.0"/>
  </joint>
  <joint name="left_shoulder_roll_joint" type="revolute">
    <parent link="left_shoulder_pitch_link"/>
    <child link="left_shoulder_roll_link"/>
    <limit effort="10" lower="-3.14" upper="3.14" velocity="3"/>
    <origin rpy="0 0 0" xyz="0 0 -0.082"/>
    <axis xyz="0 0 1"/>
    <dynamics damping="0.0"/>
  </joint>
  <joint name="left_elbow_pitch_joint" type="revolute">
    <parent link="left_shoulder_roll_link"/>
    <child link="left_elbow_pitch_link"/>
    <origin rpy="0 0 0" xyz="0 0 -0.027"/>
    <limit effort="10" lower="-1.54" upper="1.54" velocity="3"/>
    <axis xyz="1 0 0"/>
    <dynamics damping="0.0"/>
  </joint>
  <joint name="left_manipulator_joint" type="revolute">
    <parent link="left_elbow_pitch_link"/>
    <child link="left_manipulator_link"/>
    <origin rpy="0 0 0" xyz="0 0.017 -0.063"/>
    <limit effort="10" lower="-0.5" upper="0.5" velocity="3"/>
    <axis xyz="1 0 0"/>
    <dynamics damping="0.0"/>
  </joint>
  <gazebo reference="mm_uav">
  	</gazebo>
</robot>

