<robot
  name="">
  <link
    name="base_link">
    <inertial>
      <origin
        xyz="0 -0.11582 0.010769"
        rpy="0 0 0" />
      <mass
        value="0.42712" />
      <inertia
        ixx="0.0098425"
        ixy="-0.0045869"
        ixz="0.0001043"
        iyy="0.0027048"
        iyz="-0.00020852"
        izz="0.012512" />
    </inertial>
    <visual>
      <origin
        xyz="0 0 0"
        rpy="0 0 0" />
      <geometry>
        <mesh
          filename="package://arm_desription/meshes/base_link.STL" />
      </geometry>
      <material
        name="">
        <color
          rgba="0 0.50196 0.50196 1" />
      </material>
    </visual>
    <collision>
      <origin
        xyz="0 0 0"
        rpy="0 0 0" />
      <geometry>
        <mesh
          filename="package://arm_desription/meshes/base_link.STL" />
      </geometry>
    </collision>
  </link>
  <link
    name="link_1">
    <inertial>
      <origin
        xyz="0.0873 -0.19936 -0.010769"
        rpy="0 0 0" />
      <mass
        value="0.42712" />
      <inertia
        ixx="0.010504"
        ixy="-0.0039846"
        ixz="-8.403E-05"
        iyy="0.0020429"
        iyz="0.00021748"
        izz="0.012512" />
    </inertial>
    <visual>
      <origin
        xyz="0 0 0"
        rpy="0 0 0" />
      <geometry>
        <mesh
          filename="package://arm_desription/meshes/link_1.STL" />
      </geometry>
      <material
        name="">
        <color
          rgba="0.79608 0.82353 0.93725 1" />
      </material>
    </visual>
    <collision>
      <origin
        xyz="0 0 0"
        rpy="0 0 0" />
      <geometry>
        <mesh
          filename="package://arm_desription/meshes/link_1.STL" />
      </geometry>
    </collision>
  </link>
  <joint
    name="joint_joint_0"
    type="continuous">
    <origin
      xyz="-0.030938 0 0.08292"
      rpy="1.5708 0.83252 -3.1416" />
    <parent
      link="base_link" />
    <child
      link="link_1" />
    <axis
      xyz="0 0 1" />
    <limit
      lower="0"
      upper="0"
      effort="0"
      velocity="0" />
    <calibration
      rising="0"
      falling="0" />
    <dynamics
      damping="0"
      friction="0" />
    <safety_controller
      soft_lower_limit="0"
      soft_upper_limit="0"
      k_position="0"
      k_velocity="0" />
  </joint>
  <link
    name="link_2">
    <inertial>
      <origin
        xyz="-0.1104 -0.018385 0.019231"
        rpy="0 0 0" />
      <mass
        value="0.42712" />
      <inertia
        ixx="0.0028849"
        ixy="0.0047216"
        ixz="0.00020838"
        iyy="0.0096623"
        iyz="0.00010458"
        izz="0.012512" />
    </inertial>
    <visual>
      <origin
        xyz="0 0 0"
        rpy="0 0 0" />
      <geometry>
        <mesh
          filename="package://arm_desription/meshes/link_2.STL" />
      </geometry>
      <material
        name="">
        <color
          rgba="0.79608 0.82353 0.93725 1" />
      </material>
    </visual>
    <collision>
      <origin
        xyz="0 0 0"
        rpy="0 0 0" />
      <geometry>
        <mesh
          filename="package://arm_desription/meshes/link_2.STL" />
      </geometry>
    </collision>
  </link>
  <joint
    name="joint_joint_1"
    type="fixed">
    <origin
      xyz="0.079628 -0.087702 -0.03"
      rpy="-1.1789E-17 1.2189E-16 1.4744" />
    <parent
      link="link_1" />
    <child
      link="link_2" />
    <axis
      xyz="0 0 0" />
    <limit
      lower="0"
      upper="0"
      effort="0"
      velocity="0" />
    <calibration
      rising="0"
      falling="0" />
    <dynamics
      damping="0"
      friction="0" />
    <safety_controller
      soft_lower_limit="0"
      soft_upper_limit="0"
      k_position="0"
      k_velocity="0" />
  </joint>
  <link
    name="link_3">
    <inertial>
      <origin
        xyz="-0.020377 -0.074677 0.0092306"
        rpy="0 0 0" />
      <mass
        value="0.42712" />
      <inertia
        ixx="0.011916"
        ixy="-0.0013946"
        ixz="-2.6094E-05"
        iyy="0.00063166"
        iyz="0.00023168"
        izz="0.012512" />
    </inertial>
    <visual>
      <origin
        xyz="0 0 0"
        rpy="0 0 0" />
      <geometry>
        <mesh
          filename="package://arm_desription/meshes/link_3.STL" />
      </geometry>
      <material
        name="">
        <color
          rgba="0.9098 0.44314 0.031373 1" />
      </material>
    </visual>
    <collision>
      <origin
        xyz="0 0 0"
        rpy="0 0 0" />
      <geometry>
        <mesh
          filename="package://arm_desription/meshes/link_3.STL" />
      </geometry>
    </collision>
  </link>
  <joint
    name="joint_joint_2"
    type="fixed">
    <origin
      xyz="-0.033286 -0.01169 0.01"
      rpy="0 0 -1.2178" />
    <parent
      link="link_2" />
    <child
      link="link_3" />
    <axis
      xyz="0 0 0" />
    <limit
      lower="0"
      upper="0"
      effort="0"
      velocity="0" />
    <calibration
      rising="0"
      falling="0" />
    <dynamics
      damping="0"
      friction="0" />
    <safety_controller
      soft_lower_limit="0"
      soft_upper_limit="0"
      k_position="0"
      k_velocity="0" />
  </joint>
</robot>
