<robot
  name="MK2 SYSTEM_gimbal_2_links">
  <link
    name="base_link">
    <inertial>
      <origin
        xyz="-0.0275515088004856 -0.0396437317690797 0.040046107097879"
        rpy="0 0 0" />
      <mass
        value="0.257893529343319" />
      <inertia
        ixx="0.000365969470662888"
        ixy="2.47343445328342E-07"
        ixz="-1.07880792133606E-06"
        iyy="0.000583973070426484"
        iyz="1.62506348357443E-07"
        izz="0.00024907089407164" />
    </inertial>
    <visual>
      <origin
        xyz="0 0 0"
        rpy="0 0 0" />
      <geometry>
        <mesh
          filename="package://arm_description/meshes/base_link.STL" />
      </geometry>
      <material
        name="">
        <color
          rgba="0.792156862745098 0.819607843137255 0.933333333333333 1" />
      </material>
    </visual>
    <collision>
      <origin
        xyz="0 0 0"
        rpy="0 0 0" />
      <geometry>
        <mesh
          filename="package://arm_description/meshes/base_link.STL" />
      </geometry>
    </collision>
  </link>
  <link
    name="Empty_Link">
    <inertial>
      <origin
        xyz="6.50580099861853E-09 0.00650644619212175 7.81829515017485E-09"
        rpy="0 0 0" />
      <mass
        value="0.660464928508794" />
      <inertia
        ixx="0.00110828218416093"
        ixy="6.0430230538691E-10"
        ixz="1.74624701377154E-08"
        iyy="0.00195590269833561"
        iyz="5.9803343364889E-10"
        izz="0.0021628780846228" />
    </inertial>
    <visual>
      <origin
        xyz="0 0 0"
        rpy="0 0 0" />
      <geometry>
        <mesh
          filename="package://MK2 SYSTEM_gimbal_2_links/meshes/Empty_Link.STL" />
      </geometry>
      <material
        name="">
        <color
          rgba="0.792156862745098 0.819607843137255 0.933333333333333 1" />
      </material>
    </visual>
    <collision>
      <origin
        xyz="0 0 0"
        rpy="0 0 0" />
      <geometry>
        <mesh
          filename="package://MK2 SYSTEM_gimbal_2_links/meshes/Empty_Link.STL" />
      </geometry>
    </collision>
  </link>
  <joint
    name="joint"
    type="continuous">
    <origin
      xyz="-0.0274366691607497 -0.0401215575327001 0"
      rpy="1.5707963267949 0 0" />
    <parent
      link="base_link" />
    <child
      link="Empty_Link" />
    <axis
      xyz="0 -1 0" />
  </joint>
</robot>
