<robot
  name="Gimbal_torso">
  <link
    name="gimbal_base_link">
    <inertial>
      <origin
        xyz="0.697730712652662 -0.61423613512963 0.0953054578075344"
        rpy="0 0 0" />
      <mass
        value="0.220004714037555" />
      <inertia
        ixx="0.000329104039004711"
        ixy="1.84945148884467E-07"
        ixz="-1.07919275499797E-06"
        iyy="0.00052362622412332"
        iyz="1.21510237523141E-07"
        izz="0.000212205129514198" />
    </inertial>
    <visual>
      <origin
        xyz="0 0 0"
        rpy="0 0 0" />
      <geometry>
        <mesh
          filename="package://Gimbal_torso/meshes/gimbal_base_link.STL" />
      </geometry>
      <material
        name="">
        <color
          rgba="0.792156862745098 0.819607843137255 0.933333333333333 1" />
      </material>
    </visual>
    <collision>
      <origin
        xyz="0 0 0"
        rpy="0 0 0" />
      <geometry>
        <mesh
          filename="package://Gimbal_torso/meshes/gimbal_base_link.STL" />
      </geometry>
    </collision>
  </link>
  <link
    name="gimbal_yaw_link">
    <inertial>
      <origin
        xyz="6.9473E-09 -0.1105 7.1443E-09"
        rpy="0 0 0" />
      <mass
        value="0.66047" />
      <inertia
        ixx="0.0011083"
        ixy="5.3867E-10"
        ixz="1.7212E-08"
        iyy="0.0019559"
        iyz="6.5501E-10"
        izz="0.0021629" />
    </inertial>
    <visual>
      <origin
        xyz="0 0 0"
        rpy="0 0 0" />
      <geometry>
        <mesh
          filename="package://Gimbal_torso/meshes/gimbal_yaw_link.STL" />
      </geometry>
      <material
        name="">
        <color
          rgba="0.79216 0.81961 0.93333 1" />
      </material>
    </visual>
    <collision>
      <origin
        xyz="0 0 0"
        rpy="0 0 0" />
      <geometry>
        <mesh
          filename="package://Gimbal_torso/meshes/gimbal_yaw_link.STL" />
      </geometry>
    </collision>
  </link>
  <joint
    name="gimbal_yaw_joint"
    type="continuous">
    <origin
      xyz="0.69787 -0.095394 -0.45928"
      rpy="1.5708 1.1605E-19 0.0018953" />
    <parent
      link="gimbal_base_link" />
    <child
      link="gimbal_yaw_link" />
    <axis
      xyz="0 -1 0" />
  </joint>
  <link
    name="gimbal_pitch_link">
    <inertial>
      <origin
        xyz="-0.0018808 0.040513 2.2934E-08"
        rpy="0 0 0" />
      <mass
        value="0.22273" />
      <inertia
        ixx="0.00053005"
        ixy="-1.8793E-05"
        ixz="-1.0251E-08"
        iyy="0.00048715"
        iyz="-2.5611E-09"
        izz="0.00067305" />
    </inertial>
    <visual>
      <origin
        xyz="0 0 0"
        rpy="0 0 0" />
      <geometry>
        <mesh
          filename="package://Gimbal_torso/meshes/gimbal_pitch_link.STL" />
      </geometry>
      <material
        name="">
        <color
          rgba="0.79216 0.81961 0.93333 1" />
      </material>
    </visual>
    <collision>
      <origin
        xyz="0 0 0"
        rpy="0 0 0" />
      <geometry>
        <mesh
          filename="package://Gimbal_torso/meshes/gimbal_pitch_link.STL" />
      </geometry>
    </collision>
  </link>
  <joint
    name="gimbal_pitch_joint"
    type="continuous">
    <origin
      xyz="0 -0.04 0"
      rpy="1.5708 1.5684 1.5708" />
    <parent
      link="gimbal_yaw_link" />
    <child
      link="gimbal_pitch_link" />
    <axis
      xyz="0 0 -1" />
  </joint>
  <link
    name="gimbal_roll_link">
    <inertial>
      <origin
        xyz="0.0011234 0.25248 -2.1452E-08"
        rpy="0 0 0" />
      <mass
        value="1.0691" />
      <inertia
        ixx="0.028215"
        ixy="0.00010924"
        ixz="-1.0872E-09"
        iyy="0.0020241"
        iyz="-1.2535E-09"
        izz="0.027072" />
    </inertial>
    <visual>
      <origin
        xyz="0 0 0"
        rpy="0 0 0" />
      <geometry>
        <mesh
          filename="package://Gimbal_torso/meshes/gimbal_roll_link.STL" />
      </geometry>
      <material
        name="">
        <color
          rgba="0.79216 0.81961 0.93333 1" />
      </material>
    </visual>
    <collision>
      <origin
        xyz="0 0 0"
        rpy="0 0 0" />
      <geometry>
        <mesh
          filename="package://Gimbal_torso/meshes/gimbal_roll_link.STL" />
      </geometry>
    </collision>
  </link>
  <joint
    name="gimbal_roll_joint"
    type="continuous">
    <origin
      xyz="0 0.08 0"
      rpy="-3.1404 -4.4405E-14 -3.1416" />
    <parent
      link="gimbal_pitch_link" />
    <child
      link="gimbal_roll_link" />
    <axis
      xyz="-1 0 0" />
  </joint>
</robot>